Workbook

Sheet Summary
F2: BUY | G2: =IF(G11<=-15%,"BÁN",IF(G11<=-7%,"GIẢM",IF(G11<=7%,"THEO DÕI",IF(G11<15%,"THÊM","MUA")))) -> THEO DÕI | H2: =IF(H11<=-15%,"BÁN",IF(H11<=-7%,"GIẢM",IF(H11<=7%,"THEO DÕI",IF(H11<15%,"THÊM","MUA")))) -> THEO DÕI
B3: Valuation method | D3: Percentage | F3: =IF(F12<=-15%,"BÁN",IF(F12<=-7%,"GIẢM",IF(F12<=7%,"THEO DÕI",IF(F12<15%,"THÊM","MUA")))) -> THEO DÕI | G3: =IF(G12<=-15%,"BÁN",IF(G12<=-7%,"GIẢM",IF(G12<=7%,"THEO DÕI",IF(G12<15%,"THÊM","MUA")))) -> MUA | H3: =IF(H12<=-15%,"BÁN",IF(H12<=-7%,"GIẢM",IF(H12<=7%,"THEO DÕI",IF(H12<15%,"THÊM","MUA")))) -> THEO DÕI
B4: FCFF | D4: 0.7 | F4: =IF(F13<=-15%,"BÁN",IF(F13<=-7%,"GIẢM",IF(F13<=7%,"THEO DÕI",IF(F13<15%,"THÊM","MUA")))) -> THEO DÕI | G4: =IF(G13<=-15%,"BÁN",IF(G13<=-7%,"GIẢM",IF(G13<=7%,"THEO DÕI",IF(G13<15%,"THÊM","MUA")))) -> THEO DÕI | H4: =IF(H13<=-15%,"BÁN",IF(H13<=-7%,"GIẢM",IF(H13<=7%,"THEO DÕI",IF(H13<15%,"THÊM","MUA")))) -> THEO DÕI
B5: Multiple | D5: 0.3 | F5: =IF(F14<=-15%,"BÁN",IF(F14<=-7%,"GIẢM",IF(F14<=7%,"THEO DÕI",IF(F14<15%,"THÊM","MUA")))) -> THEO DÕI | G5: =IF(G14<=-15%,"BÁN",IF(G14<=-7%,"GIẢM",IF(G14<=7%,"THEO DÕI",IF(G14<15%,"THÊM","MUA")))) -> THEO DÕI | H5: =IF(H14<=-15%,"BÁN",IF(H14<=-7%,"GIẢM",IF(H14<=7%,"THEO DÕI",IF(H14<15%,"THÊM","MUA")))) -> THEO DÕI
B7: Recommendation
B8: Current price (06/06/2022) | D8: 153000
B10: Target price | D10: =D4*DCF!B41+Multiple!R38*Summary!D5 -> 191125.55
B12: Upside | D12: =(D10-D8)/D8 -> 0.24918659 | G12: Unit: VND

Sheet DATA
B1: MWG | C1: 2017 | D1: 2018 | E1: 2019 | F1: 2020 | G1: 2021
B2: Audit Committee | C2: EY | D2: EY | E2: EY | F2: EY | G2: EY
B3: Audit Opinion | C3: Unqualified opinion | D3: Unqualified opinion | E3: Unqualified opinion | F3: Unqualified opinion | G3: Unqualified opinion
B4: BALANCE SHEET
B6: A. CURRENT ASSETS | C6: 18862861 | D6: 23371995 | E6: 35011897 | F6: 37317234 | G6: 51955258
B8: I. Cash and Cash Equivalents | C8: 3410983.4 | D8: 3749550.3 | E8: 3115236.8 | F8: 7347857.4 | G8: 4142015.8
B9: 1. Cash | C9: 2189863.3 | D9: 3363717.3 | E9: 2024347.9 | F9: 2243274.5 | G9: 2606672.3
B10: 2. Cash equivalents | C10: 1221120.1 | D10: 385833 | E10: 1090888.9 | F10: 5104582.9 | G10: 1535343.5
B12: II. Short-term Financial Investment | C12: 0 | D12: 50922.5 | E12: 3137000 | F12: 8057318.8 | G12: 14236626
B13: 1. Securities available for sale | C13: 0 | D13: 0 | E13: 0 | F13: 0 | G13: 0
B14: 2. Provision for decline in value of investments in securities | C14: 0 | D14: 0 | E14: 0 | F14: 0 | G14: 0
B15: 3. Securities hold to maturity | C15: 0 | D15: 50922.5 | E15: 3137000 | F15: 8057318.8 | G15: 14236626
B17: III. Short-term Receivables | C17: 2765847.8 | D17: 1542529.7 | E17: 1815085.6 | F17: 1595251 | G17: 3162122 | J17: =IS!D3/AVERAGE(D27:E27) -> 3.8288354
B18: 1. Short-term receivables from customers | C18: 1431776.8 | D18: 369573.7 | E18: 262268.4 | F18: 196394.5 | G18: 384236.6
B19: 2. Prepaid for suppliers | C19: 117942 | D19: 21007.3 | E19: 195016.8 | F19: 287913.3 | G19: 390738.8
B20: 3. Internal short-term receivables | C20: 0 | D20: 0 | E20: 0 | F20: 0 | G20: 0
B21: 4. Receivables according to construction contract progress | C21: 0 | D21: 0 | E21: 0 | F21: 0 | G21: 0
B22: 5. Short-term loan receivable | C22: 84700 | D22: 0 | E22: 0 | F22: 80000 | G22: 961917.7
B23: 6. Other short-term receivables | C23: 1131428.9 | D23: 1151948.8 | E23: 1357800.4 | F23: 1030943.1 | G23: 1425228.9
B24: 7. Provision for short-term doubtful receivables | C24: 0 | D24: 0 | E24: 0 | F24: 0 | G24: 0
B25: 8. Assets missing pending for resolution | C25: 0 | D25: 0 | E25: 0 | F25: 0 | G25: 0
B27: IV. Inventory | C27: 12050163 | D27: 17446005 | E27: 25745428 | F27: 19422178 | G27: 29167232
B28: 1. Inventory | C28: 12309956 | D28: 17821138 | E28: 26195935 | F28: 19926364 | G28: 29850069
B29: 2. Provision for devaluation of inventory | C29: -259792.8 | D29: -375132.3 | E29: -450506.2 | F29: -504186 | G29: -682836.5
B31: V. Other Current Asset | C31: 635867.5 | D31: 582987 | E31: 1199146.1 | F31: 894629.3 | G31: 1247261.4
... B141: TOTAL EQUITY | C141: 22822664 | D141: 28122532 | E141: 41708096 | F141: 46030880 | G141: 62971405
B144: INCOME STATEMENT
B145: Audit Committee | C145: EY | D145: EY | E145: EY | F145: EY | G145: EY
B146: Audit Opinion | C146: Unqualified opinion | D146: Unqualified opinion | E146: Unqualified opinion | F146: Unqualified opinion | G146: Unqualified opinion
B148: 1. Revenue from sale of goods and services | C148: 67698541 | D148: 87738379 | E148: 1.0348505e+08 | F148: 1.0980125e+08 | G148: 1.2414153e+08
B150: 2. Deduction | C150: 1358736.5 | D150: 1222092 | E150: 1310802.7 | F150: 1255234 | G150: 1183419.6
B152: 3. Net revenue from sale of goods and services | C152: 66339804 | D152: 86516287 | E152: 102174244 | F152: 1.0854602e+08 | G152: 1.2295811e+08
B154: 4. Costs of goods sold | C154: 55198025 | D154: 71224159 | E154: 82686445 | F154: 84591522 | G154: 95325974
B156: 5. Gross profit | C156: 11141779 | D156: 15292128 | E156: 19487799 | F156: 23954497 | G156: 27632132
B158: 6. Income from financial activities | C158: 250509.8 | D158: 342083.9 | E158: 631177.9 | F158: 794121.8 | G158: 1287956
B160: 7. Expenses from financial activities | C160: 234286.6 | D160: 436573.2 | E160: 569754.8 | F160: 594151.5 | G160: 714707.2
B161: - In which: Interest expenses | C161: 233202.3 | D161: 436416.6 | E161: 568136.7 | F161: 594003.8 | G161: 674427.7
B163: 8. Share in profits of associates | C163: 0 | D163: -2101 | E163: -3473.3 | F163: -3706.9 | G163: -2210.5
B165: 9. Selling expenses | C165: 7017061.3 | D165: 9659741.2 | E165: 12437283 | F165: 15333799 | G165: 17914173
B167: 10. General and administrative expenses | C167: 1345497.4 | D167: 1761613.9 | E167: 2073782.9 | F167: 3404431.8 | G167: 3823390.1
...

Sheet ASSUMPTION
A3: Statement | B3: Assumptions | C3: Explanations | G3: 2022F | H3: 2023F | I3: 2024F | J3: 2025F | K3: 2026F
A4: INCOME STATEMENT
A5: Thegioididong.com | B5: MWG has proactively reduced the number of stores, with some being converted into Dienmayxanh. It is expected that an average of 20-30 stores will be converted each year. In 2022, an estimated 30 stores will be converted, and the Thegioididong chain will add 30 new stores. The number of new openings will gradually decrease, and by 2026, the total number of stores after conversions and new openings is expected to decrease by 25. Revenue per store (overall SSSG) is forecasted to increase by 7% in 2022, then decline to 5% in 2023, 3% in 2024, and stabilize at 1.5% in the following years. | C5: Currently, both market share and growth in the phone and laptop segments have slowed and shown signs of stagnation. If Thegioididong wants to expand, it will have to take market share from other chains, leading to intense competition. In the short term, growth will mainly come from economic recovery after the pandemic. In the mid-term, growth is expected to be driven primarily by first-time buyers and high-income customer segments. Fitch forecasts that spending on electronic devices, including PCs, audio equipment, TVs, cameras, and mobile handsets, will increase by 13.8% in value compared to the previous year. The population aged 15-64 is expected to grow at a CAGR of 0.4%. Thegioididong has also diversified its product offerings by adding watches, eyewear, and other items, which have shown strong growth. With the recovery in place, revenue growth in 2022 looks promising. Thegioididong is proactively opening new stores in high-potential locations while closing underperforming stores.
A6: Đienmayxanh | B6: This year, Dienmayxanh will open 200 more stores and take on 30 Thegioididong stores that are being converted. In the following years, new store openings will drop to an average of 80–70 for 2023 and 2024, and 50 stores for 2025–2026. Dienmayxanh’s revenue will grow by an average of 2.5% per month during 2022–2023 and 1.5% for the remaining period. | C6: According to DGW, the TV, washing machine… market currently has a scale of 2.4 billion USD. Right now, in big cities, the electronics category is almost saturated and no longer attracts as many customers as before. Meanwhile, the refrigeration segment, with products like refrigerators, is expected to recover strongly in the hot season, compared to the same period last year when shopping was affected by scattered outbreaks nationwide. Dien May Xanh Mini and Supermini are new solutions to boost revenue for MWG, using smaller store spaces to reach customers in provincial and rural areas where modern, professional retail models are still “empty.” In 2022, by continuing to open DMX Supermini (operating about 1,000 stores by the end of the year), the overall ICT and CE market is still seeing slight growth. We forecast that DMX’s revenue per store per month will increase by 2.5% in 2022 and 2023, then slow to 1.5% growth in 2024–2026 due to the industry leveling off in the long term.
A7: BLUETRONICS | B7: Open an additional 30 stores in 2022 and maintain no new openings. The overall SSG (Same-store growth) will be sustained at 5-6%. | C7: Currently, MWG has 50 stores in 13 out of 25 provinces in Cambodia. The ICT and CE markets are still very promising. However, according to the leadership, Blutronics is just a stepping stone for MWG to enter new markets in the future. Blutronics currently accounts for about half of the market's revenue, equivalent to the combined revenue of all retailers in Cambodia. Mr. Hiểu Em stated that the goal is to open an additional 30 stores to cover all 25 provinces in the neighboring country, and will stop at this number. MWG plans to expand its presence in this market and proactively maintain and grow revenue for the 80 stores in the following years.
A8: TOPZONE | B8: Open 100 new stores in 2022, reach 200 stores in 2023, and continue to open about 15–20 stores steadily in the remaining period. Revenue will hit key milestones such as 1 billion USD (over 23 trillion VND) in 2023. | C8: MWG could quickly dominate the Apple product market in Vietnam in 2022/23 thanks to the large market size of Apple products, about 34,500 billion VND, with a growth potential of around 7% per year. About 50% of the market belongs to hand-carried (grey market) products, giving MWG a big advantage in expanding its market share strongly since 2021 when stricter regulations on grey market goods were enforced. For 2022, estimated revenue is around 600 million USD. By 2023, MWG expects to reach 1 billion USD and capture 40% of the market, becoming the largest Apple distributor in the region. With two models—AAR (6–8 billion VND/month) and APPR (10–15 billion VND/month)—along with the strong "Apple" trend among Vietnamese consumers, revenue growth potential is huge. From 2023 onward, MWG has not announced further plans for TopZone, so new store openings are expected to be minimal, focusing instead on stabilizing revenue.
A9: Bachhoaxanh | B9: Open more stores aggressively starting in 2023, aiming to reach a total of 5,000 stores by 2026. The average monthly revenue per store is expected to increase by 10% in 2022, 8% in 2023, and 5% from 2024 to 2026. | C9: The retail market is very promising, with long-term growth potential and no clear market leader yet. The post-pandemic recovery has had a strong impact as workers return to their jobs and household incomes gradually recover. In 2022, MWG decided to slow down new store openings and restructure the layout and backup operations of Bách Hóa Xanh stores. This change is expected to help increase average revenue per store by 10%. However, targeting traditional markets as competitors, Bách Hóa Xanh has cut costs to lower prices on many products to match market prices. The company is also running many promotions focusing on essential goods, facing high competition from major players like MSN and Nova Consumer. As a result, in the long run, revenue growth per store is expected to decline and stabilize at 5%. With plans to expand to the North from 2023, Bách Hóa Xanh aims to reach 5,000 stores by 2026. This falls short of leadership expectations, but the Northern market is currently highly competitive, with strong competition from WinMart (MSN) and traditional markets. MSN is also aggressively expanding its minimart chains, which will pose challenges for Bách Hóa Xanh, despite its strong network advantage in the South.
A10: An Khang | B10: Opened 450 new stores in 2021, with the pace of new openings gradually slowing in the following years due to pressure from competing chains. By 2026, the total number of stores is expected to surpass 2,000. Store revenue is expected to grow strongly in 2023 and 2024, with continuous increases of 10–12%. In 2025 and 2026, growth will slow slightly to 10–8%. | C10: The pharmaceutical industry is valued at $7.4 billion, with average annual pharmaceutical spending increasing by 14%. Currently, over 95% of pharmacies in Vietnam are small retail pharmacies. After the pandemic, opportunities in the pharmaceutical sector, especially in functional foods, vitamins, etc., have expanded. This is also a suitable period for the pharmacy model to grow. An Khang has been accelerating rapidly this year and by the end of the year, it could be ranked in the top 3 in the pharmaceutical industry in terms of both revenue and the number of stores. Currently, compared to Pharmacity, this chain is targeting over 5,000 stores by 2025, and FRT aims for over 2,000 stores, competing in the large chain segment. However, the pharmaceutical market is expanding, and we expect MWG to develop 2,000 An Khang stores by 2026. With two models, An Khang combined with BHX generates a revenue of 4-500 million VND per store per month, and in the independent model, it generates 700-800 million VND per store per month. We expect the average revenue per store per month in 2022 to be around 500 million VND. With a portfolio that balances both pharmaceutical and non-pharmaceutical products, the two chains are still relatively new. Additionally, An Khang has made many strategic changes, including redefining its business model, redesigning store layouts, restructuring product categories, and launching a new website. It is expected that the revenue of this chain will continue to grow in the future and may reach an average of 732 million VND per store per month.
A11: COGS (Gross profit) | B11: Overall, the gross profit margin started to increase by 0.28% from 2022, thanks to the recovery of consumer electronics, specifically from Điện Máy Xanh and Bluetronics, along with the long-term market share growth of Apple through 2026. The gross profit margin could reach nearly 23%. | C11: The pharmaceutical industry is valued at $7.4 billion, with pharmaceutical spending growing at an average of 14% per year. Currently, over 95% of pharmacies in Vietnam are small independent stores. After the pandemic, opportunities in the pharmaceutical sector have expanded, especially for functional foods, vitamins, and supplements. This is also the right time for pharmacy chains to grow. An Khang is expanding rapidly this year and could rank in the top 3 of the pharmaceutical sector by year-end in terms of both revenue and store count. Currently competing with Pharmacity—which aims to reach over 5,000 stores by 2025—and FRT, which targets over 2,000 stores, the race to expand large chains is fierce. However, the pharmaceutical market remains wide open, and we expect MWG to develop 2,000 An Khang stores by 2026. With two models—An Khang combined with Bách Hóa Xanh (generating 400–500 million VND per month) and standalone stores (700–800 million VND per month)—we estimate the average monthly revenue per store in 2022 to be 500 million VND. By balancing its product mix between medicines and non-medicine items better than its two main competitors, An Khang is also making significant strategic changes, reshaping its business model, redesigning store layouts, restructuring its product portfolio, and launching a new website. As a result, the chain’s revenue is expected to continue growing in the future, potentially reaching an average of 732 million VND per store per month.
A16: COGS/Net Revenue | B16: 14% in 2022, then gradually stabilizing at 13.5%. | C16: The business is operating stably, but the scale expansion is not growing as fast as costs.
A17: SG&A/Net revenue | B17: Declining from 3.4% to 3.1% during 2022–2026.
A18: Other revenue | B18: Average of the last two years.
A20: Financial Income | B20: There is growth due to the efficiency of short-term financial investments.
A21: Financial Expense | B21: The average rate follows previous years.
A22: Interest rate | B22: It increases over the years as MWG maintains short-term debt to support working capital needs.
A24: Other Income
A25: Other Income/Net Revenue | B25: Average of the last two years.
A26: Other Expense
A27: Other Expense/ Net Revenue | B27: Average of the last two years.
A29: BALANCE SHEET
A31: Current Assets
A32: Average Receivable Turnover | B32: There is an improvement compared to 2021, thanks to post-pandemic recovery. In the following years, it will remain at an average level.
A33: Average Day Sales of Inventory
B34: Maintained at 3.7–3.8 days during the 2022–2026 period.
A35: Advanced payments to suppliers/Net Revenue | B35: Equal to the 2021 rate.
A36: Other Receivables/Net Revenue | B36: The average of 2021 and 2020.
A38: Non-current Assets
A39: Tangible Fixed Assets | B39: New equipment and office purchases increase in line with revenue and store count.
A40: Completed Capital Construction Investment | B40: Construction in progress is transitioned to completion.
A41: Intangible Fixed Assets | B41: New purchases remain similar to 2021 and 2020.
A42: Construction in Progress | B42: Increase in line with the pace of new store openings.
A43: Depreciation of Tangible Fixed Assets | B43: Depreciation rate matches the 2021 average.
A44: Depreciation of Intangible Fixed Assets | B44: Depreciation rate is presented in the financial statements.
A45: Goodwill | B45: Depreciation follows the regulated rate.
A47: Short-term Debt
A48: Average Accounts Payable Turnover | B48: Maintained at the three-year average from 2019–2021.
A49: Deferred Revenue/Net Revenue | B49: Remains at 0.8% each year, so this rate is expected to stay unchanged.
A50: Taxes and other Payables to the State Budget/Net Revenue | B50: Equal 2021
A51: Payables to Employees/COGS | B51: Increases steadily by 0.01% per year due to macroeconomic factors post-pandemic and workforce expansion in new chains.
A52: Short-term Payables/COGS | B52: Average of the last two years.
...

Sheet DCF
A2: The end of fiscal year | B2: 44561
A3: Valuation date | B3: 44718
A4: Year proportion | B4: =1-(B3-B2)/365 -> 0.56986301
A5: WACC | B5: =C19 -> 0.088370364
A6: Long-term growth rate | B6: 0.02
A9: WACC | C9: 2022
A10: Risk free rate | C10: 0.04
A11: Unleveraged Beta | C11: =Beta!I8 -> 0.50223651
A12: D/E | C12: =(BS!G75+BS!G86)/BS!G92 -> 1.2094993
A13: Tax rate | C13: =IS!G41 -> 0.013408104
A14: Forecasted leveraged beta | C14: =C11*(1+(1-C13)*C12) -> 1.1015464
A15: Risk premium | C15: 0.0821
A16: Cost of equity | C16: =C10+C15*C14 -> 0.13043696
A17: Interest rate | C17: ='FI&FE'!G11 -> 0.035
A18: D/(D+E) | C18: =(BS!H75/(BS!H75+BS!H92)) -> 0.43862208
A19: WACC | C19: =C16*(1-C18)+C17*C18*(1-C13) -> 0.088370364
A21: FCFF VALUATION METHOD
A23: FCFF | C23: 2022 | D23: 2023 | E23: 2024 | F23: 2025 | G23: 2026
A24: Operating profit | C24: =IS!G18 -> 6654885.6 | D24: =IS!H18 -> 8282167.8 | E24: =IS!I18 -> 10756201 | F24: =IS!J18 -> 12949266 | G24: =IS!K18 -> 14532889
A25: Depreciation | C25: =CF!G5 -> 3323046.8 | D25: =CF!H5 -> 4045858.9 | E25: =CF!I5 -> 4995898.7 | F25: =CF!J5 -> 6130873 | G25: =CF!K5 -> 7442515.6
A26: Interest rate after tax shield | C26: =IS!G7*(1-20%) -> 714965.38 | D26: =IS!H7*(1-20%) -> 760235.14 | E26: =IS!I7*(1-20%) -> 874379.52 | F26: =IS!J7*(1-20%) -> 851920.36 | G26: =IS!K7*(1-20%) -> 967668.99
A27: CAPEX | C27: =(BS!G37+BS!G43+BS!G50)-(BS!H37+BS!H43+BS!H50) -> -6437268.3 | D27: =(BS!H37+BS!H43+BS!H50)-(BS!I37+BS!I43+BS!I50) -> -7928378.5 | E27: =(BS!I37+BS!I43+BS!I50)-(BS!J37+BS!J43+BS!J50) -> -9038857.8 | F27: =(BS!J37+BS!J43+BS!J50)-(BS!K37+BS!K43+BS!K50) -> -10034881 | G27: =(BS!K37+BS!K43+BS!K50)-(BS!L37+BS!L43+BS!L50) -> -11151571
A28: Net working capital | C28: =BS!H153 -> 2078760.3 | D28: =BS!I153 -> 5694044.5 | E28: =BS!J153 -> 3394205.3 | F28: =BS!K153 -> 3770441.3 | G28: =BS!L153 -> 4232838.5
A29: FCFF | C29: =SUM(C24:C28) -> 6334389.8 | D29: =SUM(D24:D28) -> 10853928 | E29: =SUM(E24:E28) -> 10981827 | F29: =SUM(F24:F28) -> 13667620 | G29: =SUM(G24:G28) -> 16024341
A30: Mid point | C30: =B4 -> 0.56986301 | D30: =1+C30 -> 1.569863 | E30: =1+D30 -> 2.569863 | F30: =1+E30 -> 3.569863 | G30: =1+F30 -> 4.569863
A31: Discount Factor | C31: =1/((1+$B$5)^C30) -> 0.952889 | D31: =1/((1+$B$5)^D30) -> 0.87551906 | E31: =1/((1+$B$5)^E30) -> 0.80443119 | F31: =1/((1+$B$5)^F30) -> 0.7391153 | G31: =1/((1+$B$5)^G30) -> 0.67910274
A32: PV of FCFF | C32: =C31*C29 -> 6035970.4 | D32: =D31*D29 -> 9502820.8 | E32: =E31*E29 -> 8834124.1 | F32: =F31*F29 -> 10101947 | G32: =G31*G29 -> 10882174
A33: Accumalated PV of FCFF | B33: =SUM(C32:G32) -> 45357036
A34: Terminal Value | B34: =G32*(1-B6)/(B5-B6) -> 1.5598178e+08
A35: PV of Terminal Value | B35: =B34*G31 -> 1.0592765e+08
A36: Corporate value | B36: =B33+B35 -> 1.5128469e+08
A37: Cash | B37: =BS!G3 -> 4142015.8
A38: Debt | B38: =BS!G75 -> 24647474
A39: Owners' equity value | B39: =B36+B37-B38 -> 1.3077923e+08
A40: Number of shares | B40: 731854815
A41: Price | B41: =(B39*10^6)/B40 -> 178695.59

Sheet Financial Ratios
B1: 2017A | C1: 2018A | D1: 2019A | E1: 2020A | F1: 2021A | G1: 2022F | H1: 2023F | I1: 2024F | J1: 2025F | K1: 2026F
A2: LIQUIDITY RATIO
A3: Current ratio | B3: =BS!C2/BS!C65 -> 1.2003999 | C3: =BS!D2/BS!D65 -> 1.3035546 | D3: =BS!E2/BS!E65 -> 1.2309769 | E3: =BS!F2/BS!F65 -> 1.2683224 | F3: =BS!G2/BS!G65 -> 1.2198029 | G3: =BS!H2/BS!H65 -> 1.4021085 | H3: =BS!I2/BS!I65 -> 1.4037031 | I3: =BS!J2/BS!J65 -> 1.4561796 | ... K3: =BS!L2/BS!L65 -> 1.5874353
A4: Quick ratio | B4: =(BS!C2-BS!C17)/BS!C65 -> 0.43354835 | C4: =(BS!D2-BS!D17)/BS!D65 -> 0.3305174 | D4: =(BS!E2-BS!E17)/BS!E65 -> 0.32579808 | E4: =(BS!F2-BS!F17)/BS!F65 -> 0.60820965 | F4: =(BS!G2-BS!G17)/BS!G65 -> 0.5350161 | G4: =(BS!H2-BS!H17)/BS!H65 -> 0.71443956 | H4: =(BS!I2-BS!I17)/BS!I65 -> 0.65622797 | I4: =(BS!J2-BS!J17)/BS!J65 -> 0.71745601 | ... K4: =(BS!L2-BS!L17)/BS!L65 -> 0.84783809
A5: Cash Ratio | B5: =BS!C3/BS!C65 -> 0.21706908 | C5: =BS!D3/BS!D65 -> 0.20912821 | D5: =BS!E3/BS!E65 -> 0.10952804 | E5: =BS!F3/BS!F65 -> 0.24973588 | F5: =BS!G3/BS!G65 -> 0.097246035 | G5: =BS!H3/BS!H65 -> 0.31200993 | H5: =BS!I3/BS!I65 -> 0.27722135 | I5: =BS!J3/BS!J65 -> 0.35609338 | ... K5: =BS!L3/BS!L65 -> 0.53435515
A7: SOLVENCY RATIO
A8: (D+E)/E | B8: =BS!C114/BS!C92 -> 3.8624111 | C8: =BS!D114/BS!D92 -> 3.1306268 | D8: =BS!E114/BS!E92 -> 3.4345764 | E8: =BS!F114/BS!F92 -> 2.9732465 | F8: =BS!G114/BS!G92 -> 3.0901288 | G8: =BS!H114/BS!H92 -> 2.4398461 | H8: =BS!I114/BS!I92 -> 2.3647526 | I8: =BS!J114/BS!J92 -> 2.2093072 | ... K8: =BS!L114/BS!L92 -> 2.0123962
A9: Interest Coverage Ratio | B9: =(IS!B15+IS!B7)/IS!B7 -> 13.046674 | C9: =(IS!C15+IS!C7)/IS!C7 -> 9.6759271 | D9: =(IS!D15+IS!D7)/IS!D7 -> 9.8947734 | E9: =(IS!E15+IS!E7)/IS!E7 -> 10.10724 | F9: =(IS!F15+IS!F7)/IS!F7 -> 10.595667 | G9: =(IS!G15+IS!G7)/IS!G7 -> 10.612011 | H9: =(IS!H15+IS!H7)/IS!H7 -> 12.326784 | I9: =(IS!I15+IS!I7)/IS!I7 -> 13.357442 | ... K9: =(IS!K15+IS!K7)/IS!K7 -> 15.878481
A10: Cash Coverage Ratio | B10: =(IS!B15+IS!B7+CF!B5)/IS!B7 -> 16.00425 | C10: =(IS!C15+IS!C7+CF!C5)/IS!C7 -> 12.477994 | D10: =(IS!D15+IS!D7+CF!D5)/IS!D7 -> 12.43435 | E10: =(IS!E15+IS!E7+CF!E5)/IS!E7 -> 13.803485 | F10: =(IS!F15+IS!F7+CF!F5)/IS!F7 -> 14.926322 | G10: =(IS!G15+IS!G7+CF!G5)/IS!G7 -> 14.330286 | H10: =(IS!H15+IS!H7+CF!H5)/IS!H7 -> 16.584265 | I10: =(IS!I15+IS!I7+CF!I5)/IS!I7 -> 17.928363 | ... K10: =(IS!K15+IS!K7+CF!K5)/IS!K7 -> 22.031424
A12: ASSET MANAGEMENT RATIO
A13: Inventory Turnover | C13: =IS!C3/AVERAGE(BS!C17:D17) -> 4.8293839 | D13: =IS!D3/AVERAGE(BS!D17:E17) -> 3.8288354 | E13: =IS!E3/AVERAGE(BS!E17:F17) -> 3.7456722 | F13: =IS!F3/AVERAGE(BS!F17:G17) -> 3.9237346 | G13: =IS!G3/AVERAGE(BS!G17:H17) -> 3.7755055 | H13: =IS!H3/AVERAGE(BS!H17:I17) -> 3.8955772 | I13: =IS!I3/AVERAGE(BS!I17:J17) -> 3.8554166 | J13: =IS!J3/AVERAGE(BS!J17:K17) -> 3.8356452 | K13: =IS!K3/AVERAGE(BS!K17:L17) -> 3.8160756
A14: Days of inventory on hand (DOH) | C14: =365/C13 -> 75.578999 | D14: =365/D13 -> 95.329249 | E14: =365/E13 -> 97.445794 | F14: =365/F13 -> 93.023621 | G14: =365/G13 -> 96.675795 | H14: =365/H13 -> 93.696 | I14: =365/I13 -> 94.672 | J14: =365/J13 -> 95.16 | K14: =365/K13 -> 95.648
A15: Receivables Turnover | C15: =IS!C2/AVERAGE(BS!C8:D8) -> 40.161888 | D15: =IS!D2/AVERAGE(BS!D8:E8) -> 60.861198 | E15: =IS!E2/AVERAGE(BS!E8:F8) -> 63.657071 | F15: =IS!F2/AVERAGE(BS!F8:G8) -> 51.691598 | G15: =IS!G2/AVERAGE(BS!G8:H8) -> 43.87851 | H15: =IS!H2/AVERAGE(BS!H8:I8) -> 43.403416 | I15: =IS!I2/AVERAGE(BS!I8:J8) -> 41.782853 | J15: =IS!J2/AVERAGE(BS!J8:K8) -> 41.198987 | K15: =IS!K2/AVERAGE(BS!K8:L8) -> 41.205447
A16: Average Collection Period | C16: =365/C15 -> 9.0882182 | D16: =365/D15 -> 5.997253 | E16: =365/E15 -> 5.7338485 | F16: =365/F15 -> 7.0611089 | G16: =365/G15 -> 8.3184229 | H16: =365/H15 -> 8.4094763 | I16: =365/I15 -> 8.7356409 | J16: =365/J15 -> 8.8594412 | K16: =365/K15 -> 8.8580523
A17: Payable Turnover | C17: =(IS!C3+BS!D17-BS!C17)/AVERAGE(BS!C66:D66) -> 9.811854 | D17: =(IS!D3+BS!E17-BS!D17)/AVERAGE(BS!D66:E66) -> 8.964125 | E17: =(IS!E3+BS!F17-BS!E17)/AVERAGE(BS!E66:F66) -> 7.5317503 | F17: =(IS!F3+BS!G17-BS!F17)/AVERAGE(BS!F66:G66) -> 10.050824 | G17: =(IS!G3+BS!H17-BS!G17)/AVERAGE(BS!G66:H66) -> 8.9752952 | H17: =(IS!H3+BS!I17-BS!H17)/AVERAGE(BS!H66:I66) -> 9.0976918 | I17: =(IS!I3+BS!J17-BS!I17)/AVERAGE(BS!I66:J66) -> 8.9442071 | J17: =(IS!J3+BS!K17-BS!J17)/AVERAGE(BS!J66:K66) -> 8.9943267 | K17: =(IS!K3+BS!L17-BS!K17)/AVERAGE(BS!K66:L66) -> 8.8012227
A18: Average Collection Period | C18: =365/C17 -> 37.199901 | D18: =365/D17 -> 40.717861 | E18: =365/E17 -> 48.461511 | F18: =365/F17 -> 36.315431 | G18: =365/G17 -> 40.667186 | H18: =365/H17 -> 40.120067 | I18: =365/I17 -> 40.808536 | J18: =365/J17 -> 40.581137 | K18: =365/K17 -> 41.471511
A19: Assets Turnover | C19: =IS!C2/AVERAGE(BS!C63:D63) -> 3.3964454 | D19: =IS!D2/AVERAGE(BS!D63:E63) -> 2.9263447 | E19: =IS!E2/AVERAGE(BS!E63:F63) -> 2.4742942 | F19: =IS!F2/AVERAGE(BS!F63:G63) -> 2.2560647 | G19: =IS!G2/AVERAGE(BS!G63:H63) -> 2.1029668 | H19: =IS!H2/AVERAGE(BS!H63:I63) -> 2.109867 | I19: =IS!I2/AVERAGE(BS!I63:J63) -> 2.0814815 | J19: =IS!J2/AVERAGE(BS!J63:K63) -> 2.0652429 | K19: =IS!K2/AVERAGE(BS!K63:L63) -> 1.9620484
A21: PROFITABILITY RATIO
A22: Gross Profit Margin | B22: =IS!B4/IS!B2 -> 0.16795014 | C22: =IS!C4/IS!C2 -> 0.17675432 | D22: =IS!D4/IS!D2 -> 0.19073103 | E22: =IS!E4/IS!E2 -> 0.22068517 | F22: =IS!F4/IS!F2 -> 0.22472802 | G22: =IS!G4/IS!G2 -> 0.22684463 | H22: =IS!H4/IS!H2 -> 0.22531397 | I22: =IS!I4/IS!I2 -> 0.22772596 | ... K22: =IS!K4/IS!K2 -> 0.23125549
A23: Operating Profit Margin | B23: =IS!B11/IS!B2 -> 0.042138258 | C23: =IS!C11/IS!C2 -> 0.043623953 | D23: =IS!D11/IS!D2 -> 0.049275465 | E23: =IS!E11/IS!E2 -> 0.049863919 | F23: =IS!F11/IS!F2 -> 0.05258382 | G23: =IS!G11/IS!G2 -> 0.056146611 | H23: =IS!H11/IS!H2 -> 0.057101041 | I23: =IS!I11/IS!I2 -> 0.062859005 | ... K23: =IS!K11/IS!K2 -> 0.067234365
A24: Net Profit Margin | B24: =IS!B18/IS!B2 -> 0.03326656 | C24: =IS!C18/IS!C2 -> 0.033292103 | D24: =IS!D18/IS!D2 -> 0.037546058 | E24: =IS!E18/IS!E2 -> 0.036112542 | F24: =IS!F18/IS!F2 -> 0.039862575 | G24: =IS!G18/IS!G2 -> 0.043505409 | H24: =IS!H18/IS!H2 -> 0.043959399 | I24: =IS!I18/IS!I2 -> 0.050076158 | ... K24: =IS!K18/IS!K2 -> 0.054312114
A25: EBIT Margin | B25: =(IS!B15+IS!B7)/IS!B2 -> 0.045862576 | C25: =(IS!C15+IS!C7)/IS!C2 -> 0.048808558 | D25: =(IS!D15+IS!D7)/IS!D2 -> 0.055019579 | E25: =(IS!E15+IS!E7)/IS!E2 -> 0.055310542 | F25: =(IS!F15+IS!F7)/IS!F2 -> 0.058117449 | G25: =(IS!G15+IS!G7)/IS!G2 -> 0.062000528 | H25: =(IS!H15+IS!H7)/IS!H2 -> 0.062174951 | I25: =(IS!I15+IS!I7)/IS!I2 -> 0.06796814 | ... K25: =(IS!K15+IS!K7)/IS!K2 -> 0.071777864
A26: EBITDA Margin | B26: =(IS!B15+IS!B7+CF!B5)/IS!B2 -> 0.056259256 | C26: =(IS!C15+IS!C7+CF!C5)/IS!C2 -> 0.062943107 | D26: =(IS!D15+IS!D7+CF!D5)/IS!D2 -> 0.069140818 | E26: =(IS!E15+IS!E7+CF!E5)/IS!E2 -> 0.075537752 | F26: =(IS!F15+IS!F7+CF!F5)/IS!F2 -> 0.081871179 | G26: =(IS!G15+IS!G7+CF!G5)/IS!G2 -> 0.083724495 | H26: =(IS!H15+IS!H7+CF!H5)/IS!H2 -> 0.083649224 | I26: =(IS!I15+IS!I7+CF!I5)/IS!I2 -> 0.091226855 | ... K26: =(IS!K15+IS!K7+CF!K5)/IS!K2 -> 0.099591931
A27: ROA | B27: =IS!B18/BS!C63 -> 0.096697611 | C27: =IS!C18/BS!D63 -> 0.10241998 | D27: =IS!D18/BS!E63 -> 0.091978309 | E27: =IS!E18/BS!F63 -> 0.085157457 | F27: =IS!F18/BS!G63 -> 0.077835753 | G27: =IS!G18/BS!H63 -> 0.080659617 | H27: =IS!H18/BS!I63 -> 0.086193264 | I27: =IS!I18/BS!J63 -> 0.097517613 | ... K27: =IS!K18/BS!L63 -> 0.096963742
A28: ROE | B28: =IS!B18/BS!C92 -> 0.37348593 | C28: =IS!C18/BS!D92 -> 0.32063874 | D28: =IS!D18/BS!E92 -> 0.31590653 | E28: =IS!E18/BS!F92 -> 0.25319411 | F28: =IS!F18/BS!G92 -> 0.2405225 | G28: =IS!G18/BS!H92 -> 0.19679705 | H28: =IS!H18/BS!I92 -> 0.20382575 | I28: =IS!I18/BS!J92 -> 0.21544637 | ... K28: =IS!K18/BS!L92 -> 0.19512947
A29: ROAA | C29: =IS!C18/AVERAGE(BS!C63:D63) -> 0.11307481 | D29: =IS!D18/AVERAGE(BS!D63:E63) -> 0.10987271 | E29: =IS!E18/AVERAGE(BS!E63:F63) -> 0.089353054 | F29: =IS!F18/AVERAGE(BS!F63:G63) -> 0.08993255 | G29: =IS!G18/AVERAGE(BS!G63:H63) -> 0.091490429 | H29: =IS!H18/AVERAGE(BS!H63:I63) -> 0.092748487 | I29: =IS!I18/AVERAGE(BS!I63:J63) -> 0.1042326 | J29: =IS!J18/AVERAGE(BS!J63:K63) -> 0.11106801 | K29: =IS!K18/AVERAGE(BS!K63:L63) -> 0.106563
A30: ROEA | C30: =IS!C18/AVERAGE(BS!C92:D92) -> 0.38682762 | D30: =IS!D18/AVERAGE(BS!D92:E92) -> 0.36316635 | E30: =IS!E18/AVERAGE(BS!E92:F92) -> 0.28378879 | F30: =IS!F18/AVERAGE(BS!F92:G92) -> 0.27336506 | G30: =IS!G18/AVERAGE(BS!G92:H92) -> 0.24559389 | H30: =IS!H18/AVERAGE(BS!H92:I92) -> 0.22249074 | I30: =IS!I18/AVERAGE(BS!I92:J92) -> 0.23755186 | J30: =IS!J18/AVERAGE(BS!J92:K92) -> 0.23261791 | K30: =IS!K18/AVERAGE(BS!K92:L92) -> 0.213895
A31: ROIC (CFA) | B31: =((IS!B15+IS!B7)*(1-(1-IS!B18/IS!B15)))/(BS!C92+BS!C75+BS!C86-BS!C3) -> 0.2569613 | C31: =((IS!C15+IS!C7)*(1-(1-IS!C18/IS!C15)))/(BS!D92+BS!D75+BS!D86-BS!D3) -> 0.2616281 | D31: =((IS!D15+IS!D7)*(1-(1-IS!D18/IS!D15)))/(BS!E92+BS!E75+BS!E86-BS!E3) -> 0.18409206 | E31: =((IS!E15+IS!E7)*(1-(1-IS!E18/IS!E15)))/(BS!F92+BS!F75+BS!F86-BS!F3) -> 0.17481073 | F31: =((IS!F15+IS!F7)*(1-(1-IS!F18/IS!F15)))/(BS!G92+BS!G75+BS!G86-BS!G3) -> 0.13238092 | G31: =((IS!G15+IS!G7)*(1-(1-IS!G18/IS!G15)))/(BS!H92+BS!H75+BS!H86-BS!H3) -> 0.16310607 | H31: =((IS!H15+IS!H7)*(1-(1-IS!H18/IS!H15)))/(BS!I92+BS!I75+BS!I86-BS!I3) -> 0.16961123 | I31: =((IS!I15+IS!I7)*(1-(1-IS!I18/IS!I15)))/(BS!J92+BS!J75+BS!J86-BS!J3) -> 0.19499658 | ... K31: =((IS!K15+IS!K7)*(1-(1-IS!K18/IS!K15)))/(BS!L92+BS!L75+BS!L86-BS!L3) -> 0.21186162
A33: MARKET VALUE RATIO
A34: EPS | E34: =IS!E23 -> 5675.7904 | F34: =IS!F23 -> 6896.7094 | G34: =IS!G23 -> 4544.4885 | H34: =IS!H23 -> 5655.7088 | I34: =IS!I23 -> 7345.6147 | J34: =IS!J23 -> 8843.5324 | K34: =IS!K23 -> 9925.0923
A36: GROWTH RATIO
A37: Operationg Profit Growth Rate | C37: =SALE!C53 -> 0.30413841 | D37: =SALE!D53 -> 0.18098277 | E37: =SALE!E53 -> 0.062361858 | F37: =SALE!F53 -> 0.13277397 | G37: =SALE!G53 -> 0.24405669 | H37: =SALE!H53 -> 0.23167163 | I37: =SALE!I53 -> 0.14008082 | J37: =SALE!J53 -> 0.12098384 | K37: =SALE!K53 -> 0.11129149
A38: Gross Profit Margin Growth Rate | C38: =IS!C4/IS!B4-1 -> 0.37250321 | D38: =IS!D4/IS!C4-1 -> 0.27436806 | E38: =IS!E4/IS!D4-1 -> 0.22920484 | F38: =IS!F4/IS!E4-1 -> 0.15352586 | G38: =IS!G4/IS!F4-1 -> 0.25577385 | H38: =IS!H4/IS!G4-1 -> 0.22336081 | I38: =IS!I4/IS!H4-1 -> 0.1522854 | J38: =IS!J4/IS!I4-1 -> 0.13345114 | K38: =IS!K4/IS!J4-1 -> 0.11610242
A39: EBIT Growth Rate | C39: =IS!C15/IS!B15-1 -> 0.34777433 | D39: =IS!D15/IS!C15-1 -> 0.33465979 | E39: =IS!E15/IS!D15-1 -> 0.070503992 | F39: =IS!F15/IS!E15-1 -> 0.19628472 | G39: =IS!G15/IS!F15-1 -> 0.32739053 | H39: =IS!H15/IS!G15-1 -> 0.2530121 | I39: =IS!I15/IS!H15-1 -> 0.2547986 | J39: =IS!J15/IS!I15-1 -> 0.18884279 | K39: =IS!K15/IS!J15-1 -> 0.12081107
A40: EAT Growth Rate | C40: =IS!C18/IS!B18-1 -> 0.30513974 | D40: =IS!D18/IS!C18-1 -> 0.33188487 | E40: =IS!E18/IS!D18-1 -> 0.021800669 | F40: =IS!F18/IS!E18-1 -> 0.25040456 | G40: =IS!G18/IS!F18-1 -> 0.35774459 | H40: =IS!H18/IS!G18-1 -> 0.24452445 | I40: =IS!I18/IS!H18-1 -> 0.2987181 | J40: =IS!J18/IS!I18-1 -> 0.20388838 | K40: =IS!K18/IS!J18-1 -> 0.12229446
A41: Total Assets Growth Rate | C41: =BS!D63/BS!C63-1 -> 0.23221948 | D41: =BS!E63/BS!D63-1 -> 0.48308468 | E41: =BS!F63/BS!E63-1 -> 0.10364378 | F41: =BS!G63/BS!F63-1 -> 0.36802522 | G41: =BS!H63/BS!G63-1 -> 0.31021043 | H41: =BS!I63/BS!H63-1 -> 0.16462541 | I41: =BS!J63/BS!I63-1 -> 0.14790292 | J41: =BS!K63/BS!J63-1 -> 0.11402576 | K41: =BS!L63/BS!K63-1 -> 0.21975191
A42: Short-term Debt Growth Rate | C42: =BS!D65/BS!C65-1 -> 0.1409981 | D42: =BS!E65/BS!D65-1 -> 0.58635059 | E42: =BS!F65/BS!E65-1 -> 0.0344608 | F42: =BS!G65/BS!F65-1 -> 0.44763835 | G42: =BS!H65/BS!G65-1 -> 0.14313686 | H42: =BS!I65/BS!H65-1 -> 0.13893998 | I42: =BS!J65/BS!I65-1 -> 0.088723188 | J42: =BS!K65/BS!J65-1 -> 0.018093034 | K42: =BS!L65/BS!K65-1 -> 0.22669264
A43: Debt Growth Rate | C43: =BS!D64/BS!C64-1 -> 0.13159403 | D43: =BS!E64/BS!D64-1 -> 0.54468556 | E43: =BS!F64/BS!E64-1 -> 0.033306384 | F43: =BS!G64/BS!F64-1 -> 0.39424838 | G43: =BS!H64/BS!G64-1 -> 0.14313686 | H43: =BS!I64/BS!H64-1 -> 0.13893998 | I43: =BS!J64/BS!I64-1 -> 0.088723188 | J43: =BS!K64/BS!J64-1 -> 0.018093034 | K43: =BS!L64/BS!K64-1 -> 0.22669264
A44: Equity Growth Rate | C44: =BS!D92/BS!C92-1 -> 0.5202509 | D44: =BS!E92/BS!D92-1 -> 0.35183619 | E44: =BS!F92/BS!E92-1 -> 0.27488552 | F44: =BS!G92/BS!F92-1 -> 0.31628047 | G44: =BS!H92/BS!G92-1 -> 0.65941572 | H44: =BS!I92/BS!H92-1 -> 0.20160847 | I44: =BS!J92/BS!I92-1 -> 0.2286686 | J44: =BS!K92/BS!J92-1 -> 0.2300379 | K44: =BS!L92/BS!K92-1 -> 0.21280468
A46: FINANCIAL LEVERAGE GROWTH RATIO
...

Sheet M- Scores
A1: MOBILE WORLD, JSC (HOSE: MWG) Analysis of financial reporting fraud assessment index
B4: We use Beneish's M-Score to reassess the likelihood of financial statement fraud by the company.
B5: Beneish M-Score:
B6: M-Score (8 variables) = -4.48 + 0.0290xDSRI + 0.528xGMI + 0.404xAQI + 0.892xSGI + 0.115xDEPI - 0.172xSGAI + 4.679xTATA - 0.327xLVGI
B8: Financial Ratio Indexes | C8: 2017 | D8: 2018 | E8: 2019 | F8: 2020 | G8: 2021
B9: Days Sales Receivable Index (DSRI) | D9: =(D28/D26)/(C28/C26) -> 0.4276432 | E9: =(E28/E26)/(D28/D26) -> 0.99636856 | F9: =(F28/F26)/(E28/E26) -> 0.82729318 | G9: =(G28/G26)/(F28/F26) -> 1.7498722
B10: Gross Margin Index (GMI) | D10: =((C26-C27)/C26)/((D26-D27)/D26) -> 0.9501897 | E10: =((D26-D27)/D26)/((E26-E27)/E26) -> 0.92672031 | F10: =((E26-E27)/E26)/((F26-F27)/F26) -> 0.86426755 | G10: =((F26-F27)/F26)/((G26-G27)/G26) -> 0.98201004
B11: Asset Quality Index (AQI) | D11: =(1-((D29+D30)/D32))/(1-((C29+C30)/C32)) -> 2.2390839 | E11: =(1-((E29+E30)/E32))/(1-((D29+D30)/D32)) -> 0.61611001 | F11: =(1-((F29+F30)/F32))/(1-((E29+E30)/E32)) -> 0.99211306 | G11: =(1-((G29+G30)/G32))/(1-((F29+F30)/F32)) -> 0.73242886
B12: Sales Growth Index (SGI) | D12: =D26/C26 -> 1.3041384 | E12: =E26/D26 -> 1.1809828 | F12: =F26/E26 -> 1.0623619 | G12: =G26/F26 -> 1.132774
B13: Depreciation Index (DEPI) | D13: =(C31/(C30+C31))/(D31/(D30+D31)) -> 0.6408315 | E13: =(D31/(D30+D31))/(E31/(E30+E31)) -> 1.2719345 | F13: =(E31/(E30+E31))/(F31/(F30+F31)) -> 0.90086498 | G13: =(F31/(F30+F31))/(G31/(G30+G31)) -> 0.98639765
B14: Sales, General and Administration Expense Index (SGAI) | D14: =(D33/D26)/(C33/C26) -> 1.0039317 | E14: =(E33/E26)/(D33/D26) -> 0.99680223 | F14: =(F33/F26)/(E33/E26) -> 1.545286 | G14: =(G33/G26)/(F33/F26) -> 0.99142693
B15: Leverage Index (LVGI) | D15: =((D36+D37)/D32)/((C36+C37)/C32) -> 0.91833805 | E15: =((E36+E37)/E32)/((D36+D37)/D32) -> 1.0415356 | F15: =((F36+F37)/F32)/((E36+E37)/E32) -> 0.93626803 | G15: =((G36+G37)/G32)/((F36+F37)/F32) -> 1.0191686
B16: Total Accrual on Total Assets (TATA) | D16: =(D34-D35)/D32 -> 0.022017029 | E16: =(E34-E35)/E32 -> 0.12281359 | F16: =(F34-F35)/F32 -> -0.14930317 | G16: =(G34-G35)/G32 -> 0.075114035
B17: Beneish M-Score (8 biến) | E17: =-4.48 + 0.029*E9/D9 + 0.528*D10/E10 + 0.404*E11/D11 + 0.892*E12/D12 + 0.115*D13/E13 - 0.172*E14/D14 + 4.679*E16 - 0.327*E15/D15 -> -2.8611932 | F17: =-4.48 + 0.029*F9/E9 + 0.528*E10/F10 + 0.404*F11/E11 + 0.892*F12/E12 + 0.115*E13/F13 - 0.172*F14/E14 + 4.679*F16 - 0.327*F15/E15 -> -3.5336194 | G17: =-4.48 + 0.029*G9/F9 + 0.528*F10/G10 + 0.404*G11/F11 + 0.892*G12/F12 + 0.115*F13/G13 - 0.172*G14/F14 + 4.679*G16 - 0.327*G15/F15 -> -2.7144116
B19: KẾT LUẬN:
B20: MWG did not manipulate its financial statements during the 2019-2021 period.
B21: Beneish M-Score (8 variables) < -2,22: Company is not likely to have manipulated their earnings
B22: Beneish M-Score (8 variables) > -2,22: Company is likely to have manipulated their earnings
G24: Unit: Million VND
C25: 2017 | D25: 2018 | E25: 2019 | F25: 2020 | G25: 2021
B26: Net Revenue | C26: =DATA!C152 -> 66339804 | D26: =DATA!D152 -> 86516287 | E26: =DATA!E152 -> 102174244 | F26: =DATA!F152 -> 1.0854602e+08 | G26: =DATA!G152 -> 1.2295811e+08
B27: COGS | C27: =DATA!C154 -> 55198025 | D27: =DATA!D154 -> 71224159 | E27: =DATA!E154 -> 82686445 | F27: =DATA!F154 -> 84591522 | G27: =DATA!G154 -> 95325974
B28: Payables | C28: =DATA!C17 -> 2765847.8 | D28: =DATA!D17 -> 1542529.7 | E28: =DATA!E17 -> 1815085.6 | F28: =DATA!F17 -> 1595251 | G28: =DATA!G17 -> 3162122
B29: Current Assets | C29: =DATA!C6 -> 18862861 | D29: =DATA!D6 -> 23371995 | E29: =DATA!E6 -> 35011897 | F29: =DATA!F6 -> 37317234 | G29: =DATA!G6 -> 51955258
B30: PP&E | C30: =DATA!C50 -> 3435848.3 | D30: =DATA!D50 -> 3304923.5 | E30: =DATA!E50 -> 5375279.2 | F30: =DATA!F50 -> 7267319.3 | G30: =DATA!G50 -> 9566954.9
B31: Depreciation | C31: =-CAPEX!B16 -> 686732.39 | D31: =-CAPEX!C16 -> 1160832.3 | E31: =-CAPEX!D16 -> 1380695 | F31: =-CAPEX!E16 -> 2132376.3 | G31: =-CAPEX!F16 -> 2857407.2
B32: Total Assets | C32: =DATA!C81 -> 22822664 | D32: =DATA!D81 -> 28122532 | E32: =DATA!E81 -> 41708096 | F32: =DATA!F81 -> 46030880 | G32: =DATA!G81 -> 62971405
B33: SGA Expense | C33: =DATA!C167 -> 1345497.4 | D33: =DATA!D167 -> 1761613.9 | E33: =DATA!E167 -> 2073782.9 | F33: =DATA!F167 -> 3404431.8 | G33: =DATA!G167 -> 3823390.1
B34: Earnings after Tax (EAT) | C34: =DATA!C183 -> 2206897.1 | D34: =DATA!D183 -> 2880309.1 | E34: =DATA!E183 -> 3836240.1 | F34: =DATA!F183 -> 3919872.7 | G34: =DATA!G183 -> 4901426.7
B35: Cashflow from Operating Activities | C35: =DATA!C194 -> 2663664 | D35: =DATA!D194 -> 2261134.5 | E35: =DATA!E194 -> -1286080.8 | F35: =DATA!F194 -> 10792429 | G35: =DATA!G194 -> 171390.4
B36: Short-term Debt | C36: =DATA!C85 -> 15713815 | D36: =DATA!D85 -> 17929433 | E36: =DATA!E85 -> 28442367 | F36: =DATA!F85 -> 29422513 | G36: =DATA!G85 -> 42593159
B37: Long-term Debt | C37: =DATA!C101 -> 1199933 | D37: =DATA!D101 -> 1210063.2 | E37: =DATA!E101 -> 1122136.7 | F37: =DATA!F101 -> 1126676.7 | G37: =DATA!G101 -> 0

Sheet SALE
B1: 2017A | C1: 2018A | D1: 2019A | E1: 2020A | F1: 2021A | G1: 2022F | H1: 2023F | I1: 2024F | J1: 2025F | K1: 2026F
A2: ICT &CE( ĐMX, TGDĐ, Topzone, Bluetronics )
A3: Thegioididong | B3: 34708000 | C3: =0.4*C52 -> 34606515 | D3: =0.57*D52 -> 58239319 | E3: =0.272*E52 -> 29524517 | F3: =0.25662*F52 -> 31553509 | G3: =G8*G7*12 -> 34806448 | H3: =H7*H8*12 -> 37277706 | I3: =I7*I8*12 -> 38019606 | J3: =J7*J8*12 -> 37825743 | K3: =K7*K8*12 -> 37423606
A4: Growth | C4: =(C3-B3)/B3 -> -0.0029239714 | D4: =(D3-C3)/C3 -> 0.68290044 | E4: =(E3-D3)/D3 -> -0.49304838 | F4: =(F3-E3)/E3 -> 0.068722269 | G4: =(G3-F3)/F3 -> 0.10309278 | H4: =(H3-G3)/G3 -> 0.071 | I4: =(I3-H3)/H3 -> 0.019901961 | J4: =(J3-I3)/I3 -> -0.0050990099 | K4: =(K3-J3)/J3 -> -0.010631313
A5: The number of old stores | B5: 951 | C5: =B7 -> 1072 | D5: =C7 -> 1032 | E5: =D7 -> 996 | F5: =E7 -> 913 | G5: =F7 -> 970 | H5: =G7 -> 1000 | I5: =H7 -> 1020 | J5: =I7 -> 1010 | K5: =J7 -> 990
A6: The number of new stores | B6: =1072-B5 -> 121 | C6: =C7-C5 -> -40 | D6: =D7-D5 -> -36 | E6: =E7-E5 -> -83 | F6: =F7-F5 -> 57 | G6: 30 | H6: 20 | I6: -10 | J6: -20 | K6: -25
A7: Total stores | B7: =SUM(B5:B6) -> 1072 | C7: 1032 | D7: 996 | E7: 913 | F7: 970 | G7: =SUM(G5:G6) -> 1000 | H7: =SUM(H5:H6) -> 1020 | I7: =SUM(I5:I6) -> 1010 | J7: =SUM(J5:J6) -> 990 | K7: =SUM(K5:K6) -> 965
A8: Average revenue per store per month | B8: =(B3/B7)/12 -> 2698.0721 | C8: =(C3/C7)/12 -> 2794.4537 | D8: =(D3/D7)/12 -> 4872.7677 | E8: =(E3/E7)/12 -> 2694.8263 | F8: =(F3/F7)/12 -> 2710.7826 | G8: =F8*(1+G9) -> 2900.5374 | H8: =G8*(1+H9) -> 3045.5642 | I8: =H8*(1+I9) -> 3136.9312 | J8: =I8*(1+J9) -> 3183.9851 | K8: =J8*(1+K9) -> 3231.7449
A9: Same-store sales growth (SSSG) | G9: 0.07 | H9: 0.05 | I9: 0.03 | J9: 0.015 | K9: 0.015
A11: Đienmayxanh | B11: 30245000 | C11: =0.55*C52 -> 47583958 | D11: =0.325*D52 -> 33206629 | E11: =0.532*E52 -> 57746482 | F11: =0.51*F52 -> 62708634 | G11: =G16*G15*12 -> 71697816 | H11: =H16*H15*12 -> 76136175 | I11: =I16*I15*12 -> 79628120 | J11: =J16*J15*12 -> 82526222 | K11: =K16*K15*12 -> 85493349
A12: Growth | C12: =(C11-B11)/B11 -> 0.57328345 | D12: =(D11-C11)/C11 -> -0.30214655 | E12: =(E11-D11)/D11 -> 0.73900464 | F12: =(F11-E11)/E11 -> 0.085929938 | G12: =(G11-F11)/F11 -> 0.14334839 | H12: =(H11-G11)/G11 -> 0.06190369 | I12: =(I11-H11)/H11 -> 0.045864466 | J12: =(J11-I11)/I11 -> 0.036395447 | K12: =(K11-J11)/J11 -> 0.035953757
A13: The number of old stores | B13: =B15-B14 -> 256 | C13: =B15 -> 642 | D13: =C15 -> 750 | E13: =D15 -> 1018 | F13: =E15 -> 1427 | G13: =F15 -> 1992 | H13: =G15 -> 2222 | I13: =H15 -> 2302 | J13: =I15 -> 2372 | K13: =J15 -> 2422
A14: The number of new stores | B14: 386 | C14: =C15-C13 -> 108 | D14: =D15-D13 -> 268 | E14: =E15-E13 -> 409 | F14: =F15-F13 -> 565 | G14: 230 | H14: 80 | I14: 70 | J14: 50 | K14: 50
A15: Total stores | B15: 642 | C15: 750 | D15: 1018 | E15: 1427 | F15: 1992 | G15: =SUM(G13:G14) -> 2222 | H15: =SUM(H13:H14) -> 2302 | I15: =SUM(I13:I14) -> 2372 | J15: =SUM(J13:J14) -> 2422 | K15: =SUM(K13:K14) -> 2472
A16: Average revenue per store per month | B16: =(B11/B15)/12 -> 3925.8827 | C16: =(C11/C15)/12 -> 5287.1064 | D16: =(D11/D15)/12 -> 2718.2899 | E16: =(E11/E15)/12 -> 3372.2543 | F16: =(F11/F15)/12 -> 2623.3532 | G16: =F16*(1+G17) -> 2688.937 | H16: =G16*(1+H17) -> 2756.1604 | I16: =H16*(1+I17) -> 2797.5028 | J16: =I16*(1+J17) -> 2839.4654 | K16: =J16*(1+K17) -> 2882.0574
A17: Same-store sales growth (SSSG) | G17: 0.025 | H17: =G17 -> 0.025 | I17: 0.015 | J17: 0.015 | K17: 0.015
A19: Bluetronics | D19: n/a | E19: n/a | F19: =0.39%*F52 -> 479536.61 | G19: =G23*G24*12 -> 813294.1 | H19: =H23*H24*12 -> 862091.74 | I19: =I23*I24*12 -> 905196.33 | J19: =J23*J24*12 -> 950456.15 | K19: =K23*K24*12 -> 997978.95
A20: Growth | G20: =(G19/F19)-1 -> 0.696 | H20: =(H19/G19)-1 -> 0.06 | I20: =(I19/H19)-1 -> 0.05 | J20: =(J19/I19)-1 -> 0.05 | K20: =(K19/J19)-1 -> 0.05
A21: The number of old stores | B21: 0 | C21: 0 | D21: =C23 -> 10 | E21: =D23 -> 19 | F21: =E23 -> 38 | G21: =F23 -> 50 | H21: =G23 -> 80 | I21: =H23 -> 80 | J21: =I23 -> 80 | K21: =J23 -> 80
A22: The number of new stores | B22: 0 | C22: =C23-C21 -> 10 | D22: =D23-D21 -> 9 | E22: =E23-E21 -> 19 | F22: =F23-F21 -> 12 | G22: 30 | H22: 0 | I22: 0 | J22: 0 | K22: 0
A23: Total stores | B23: 0 | C23: 10 | D23: 19 | E23: 38 | F23: 50 | G23: =SUM(G21:G22) -> 80 | H23: =SUM(H21:H22) -> 80 | I23: =SUM(I21:I22) -> 80 | J23: =SUM(J21:J22) -> 80 | K23: =SUM(K21:K22) -> 80
A24: Average revenue per store per month | F24: =F19/F23/12 -> 799.22769 | G24: =F24*(1+G25) -> 847.18135 | H24: =G24*(1+H25) -> 898.01223 | I24: =H24*(1+I25) -> 942.91284 | J24: =I24*(1+J25) -> 990.05849 | K24: =J24*(1+K25) -> 1039.5614
A25: Same-store sales growth (SSSG) | G25: 0.06 | H25: 0.06 | I25: 0.05 | J25: 0.05 | K25: 0.05
A27: Topzone | F27: n/a | G27: =G32*G31*12 -> 9900000 | H27: =H32*H31*12 -> 22140000 | I27: =I32*I31*12 -> 26058780 | J27: =J32*J31*12 -> 29784001 | K27: =K32*K31*12 -> 33903065
A28: Growth | H28: =(H27/G27)-1 -> 1.2363636 | I28: =(I27/H27)-1 -> 0.177 | J28: =(J27/I27)-1 -> 0.14295455 | K28: =(K27/J27)-1 -> 0.13829787
A29: The number of old stores | B29: 0 | C29: 0 | D29: 0 | E29: 0 | F29: 0 | G29: =F31 -> 10 | H29: =G31 -> 110 | I29: =H31 -> 200 | J29: =I31 -> 220 | K29: =J31 -> 235
A30: The number of new stores | B30: 0 | C30: 0 | D30: 0 | E30: 0 | F30: 10 | G30: 100 | H30: 90 | I30: 20 | J30: 15 | K30: 15
A31: Total stores | B31: 0 | C31: 0 | D31: 0 | E31: 0 | F31: 10 | G31: =SUM(G29:G30) -> 110 | H31: =SUM(H29:H30) -> 200 | I31: =SUM(I29:I30) -> 220 | J31: =SUM(J29:J30) -> 235 | K31: =SUM(K29:K30) -> 250
A32: Average revenue per store per month | G32: =7500 -> 7500 | H32: =G32*1.23 -> 9225 | I32: =H32*1.07 -> 9870.75 | J32: =I32*1.07 -> 10561.703 | K32: =J32*1.07 -> 11301.022
A33: Same-store sales growth (SSSG) | H33: 0.23 | I33: 0.07 | J33: 0.07 | K33: 0.07
A35: FMCG
A36: Bachhoaxanh | B36: =B52-B3-B11 -> 1386804.2 | C36: =C52-C3-C11 -> 4325814.3 | D36: =D52-D3-D11 -> 10728296 | E36: =E52-E3-E11 -> 21275020 | F36: =F52-F3-F11-F19 -> 28216426 | G36: =G41*G40*12 -> 31981296 | H36: =H41*H40*12 -> 45204162 | I36: =I41*I40*12 -> 59998975 | J36: =J41*J40*12 -> 75809289 | K36: =K41*K40*12 -> 92129345
A37: Growth | C37: =(C36-B36)/B36 -> 2.1192683 | D37: =(D36-C36)/C36 -> 1.4800638 | E37: =(E36-D36)/D36 -> 0.98307547 | F37: =(F36-E36)/E36 -> 0.32627026 | G37: =(G36-F36)/F36 -> 0.1334283 | H37: =(H36-G36)/G36 -> 0.41345622 | I37: =(I36-H36)/H36 -> 0.32728873 | J37: =(J36-I36)/I36 -> 0.26350975 | K37: =(K36-J36)/J36 -> 0.21527778
A38: The number of old stores | B38: =B40-B39 -> 48 | C38: =B40 -> 283 | D38: =C40 -> 405 | E38: =D40 -> 1008 | F38: =E40 -> 1719 | G38: =F40 -> 2106 | H38: =G40 -> 2170 | I38: =H40 -> 2840 | J38: =I40 -> 3590 | K38: =J40 -> 4320
A39: The number of new stores | B39: 235 | C39: =C40-C38 -> 122 | D39: =D40-D38 -> 603 | E39: =E40-E38 -> 711 | F39: =F40-F38 -> 387 | G39: 64 | H39: 670 | I39: 750 | J39: 730 | K39: 680
A40: Total stores | B40: 283 | C40: 405 | D40: 1008 | E40: 1719 | F40: 2106 | G40: =SUM(G38:G39) -> 2170 | H40: =SUM(H38:H39) -> 2840 | I40: =SUM(I38:I39) -> 3590 | J40: =SUM(J38:J39) -> 4320 | K40: =SUM(K38:K39) -> 5000
A41: Average revenue per store per month | B41: =B36/B40/12 -> 408.36402 | C41: =C36/C40/12 -> 890.08526 | D41: =D36/D40/12 -> 886.9292 | E41: =E36/E40/12 -> 1031.3661 | F41: =F36/F40/12 -> 1116.5094 | G41: =F41*(1+G42) -> 1228.1604 | H41: =G41*(1+H42) -> 1326.4132 | I41: =H41*(1+I42) -> 1392.7339 | J41: =I41*(1+J42) -> 1462.3705 | K41: =J41*(1+K42) -> 1535.4891
A42: Same-store sales growth (SSSG) | G42: 0.1 | H42: 0.08 | I42: 0.05 | J42: 0.05 | K42: 0.05
A44: Pharmaceutical
A45: An Khang | E45: n/a | F45: n/a | G45: =G49*G50*12 -> 3768000 | H45: =H49*H50*12 -> 6784800 | I45: =I49*I50*12 -> 10186176 | J45: =J49*J50*12 -> 13888090 | K45: =K49*K50*12 -> 17633646
...

Sheet IS
A1: MWG (Unit: Million VND) | B1: 2017 | C1: 2018 | D1: 2019 | E1: 2020 | F1: 2021 | G1: 2022F | H1: 2023F | I1: 2024F | J1: 2025F | K1: 2026F
A2: 1. Net revenue from sale of goods and services | B2: 66339804 | C2: 86516287 | D2: 102174244 | E2: 1.0854602e+08 | F2: 1.2295811e+08 | G2: =SALE!G52 -> 1.5296685e+08 | H2: =SALE!H52 -> 1.8840494e+08 | I2: =SALE!I52 -> 2.1479685e+08 | J2: =SALE!J52 -> 2.407838e+08 | K2: =SALE!K52 -> 2.6758099e+08
A3: 2. Costs of goods sold | B3: 55198025 | C3: 71224159 | D3: 82686445 | E3: 84591522 | F3: 95325974 | G3: =G59 -> 1.1826715e+08 | H3: =H59 -> 1.4595467e+08 | I3: =I59 -> 1.6588203e+08 | J3: =J59 -> 1.8534124e+08 | K3: =K59 -> 2.0570142e+08
A4: 3. Gross profit | B4: 11141779 | C4: 15292128 | D4: 19487799 | E4: 23954497 | F4: 27632132 | G4: =G2-G3 -> 34699709 | H4: =H2-H3 -> 42450264 | I4: =I2-I3 -> 48914819 | J4: =J2-J3 -> 55442558 | K4: =K2-K3 -> 61879573 | M4: 1. Revenue from sale of goods and services
A5: 4. Income from financial activities | B5: 250509.8 | C5: 342083.9 | D5: 631177.9 | E5: 794121.8 | F5: 1287956 | G5: =F5*1.05 -> 1352353.8 | H5: =G5*1.05 -> 1419971.5 | I5: =H5*1.05 -> 1490970.1 | J5: =I5*1.06 -> 1580428.3 | K5: =J5*1.06 -> 1675254 | M5: 2. Costs of goods sold
A6: 5. Expenses from financial activities | B6: 234286.6 | C6: 436573.2 | D6: 569754.8 | E6: 594151.5 | F6: 714707.2 | G6: =G2*G31+G7 -> 904810.26 | H6: =H2*H31+H7 -> 966089.13 | I6: =I2*I31+I7 -> 1114506 | J6: =J2*J31+J7 -> 1093101.7 | K6: =K2*K31+K7 -> 1247121.2 | M6: 3. Gross profit
A7: - In which: Interest expenses | B7: 233202.3 | C7: 436416.6 | D7: 568136.7 | E7: 594003.8 | F7: 674427.7 | G7: ='FI&FE'!G2 -> 893706.73 | H7: ='FI&FE'!H2 -> 950293.92 | I7: ='FI&FE'!I2 -> 1092974.4 | J7: ='FI&FE'!J2 -> 1064900.5 | K7: ='FI&FE'!K2 -> 1209586.2 | M7: 4. Income from financial activities
A8: 6. Gain (loss) in profits of associates | B8: 0 | C8: -2101 | D8: -3473.3 | E8: -3706.9 | F8: -2210.5 | G8: =G2*G33 -> -4391.273 | H8: =H2*H33 -> -5076.603 | I8: =I2*I33 -> -5271.8442 | J8: =J2*J33 -> -6436.6258 | K8: =K2*K33 -> -6976.7763 | M8: 5. Expenses from financial activities
A9: 7. Selling expenses | B9: 7017061.3 | C9: 9659741.2 | D9: 12437283 | E9: 15333799 | F9: 17914173 | G9: =G2*G34 -> 21415360 | H9: =H2*H34 -> 25811476 | I9: =I2*I34 -> 28997575 | J9: =J2*J34 -> 32505813 | K9: =K2*K34 -> 36123434 | M9: - In which: Interest expenses
A10: 8. General and administrative expenses | B10: 1345497.4 | C10: 1761613.9 | D10: 2073782.9 | E10: 3404431.8 | F10: 3823390.1 | G10: =G2*G35 -> 5138931.2 | H10: =H2*H35 -> 6329475.7 | I10: =I2*I35 -> 6786520.2 | J10: =J2*J35 -> 7366795.6 | K10: =K2*K35 -> 8186657.3 | M10: 6. Share in profits of associates
A11: 9. Operating profit | B11: 2795443.8 | C11: 3774182.4 | D11: 5034683.4 | E11: 5412529.9 | F11: 6465606.9 | G11: =G4+G5-G6+G8-G9-G10 -> 8588570.4 | H11: =H4+H5-H6+H8-H9-H10 -> 10758118 | I11: =I4+I5-I6+I8-I9-I10 -> 13501916 | J11: =J4+J5-J6+J8-J9-J10 -> 16050839 | K11: =K4+K5-K6+K8-K9-K10 -> 17990638 | M11: 7. Selling expenses
A12: 10. Other income | B12: 17684.6 | C12: 33233.3 | D12: 41557 | E12: 43512.7 | F12: 54872.8 | G12: =G$2*G37 -> 64792.248 | H12: =H$2*H37 -> 81941.341 | I12: =I$2*I37 -> 92200.681 | J12: =J$2*J37 -> 104038.75 | K12: =K$2*K37 -> 115237.72 | M12: 8. General and administrative expenses
A13: 11. Other expenses | B13: 3816.4 | C13: 21097.2 | D13: 22793.3 | E13: 46307.2 | F13: 48896 | G13: =G$2*G38 -> 63043.562 | H13: =H$2*H38 -> 76285.404 | I13: =I$2*I38 -> 87748.812 | J13: =J$2*J38 -> 97929.338 | K13: =K$2*K38 -> 109070.11 | M13: 9. Operating profit
A14: 12. Other profit | B14: 13868.3 | C14: 12136.2 | D14: 18763.8 | E14: -2794.5 | F14: 5976.8 | G14: =G12-G13 -> 1748.6854 | H14: =H12-H13 -> 5655.9367 | I14: =I12-I13 -> 4451.869 | J14: =J12-J13 -> 6109.4146 | K14: =K12-K13 -> 6167.6055 | M14: 10. Other income
A15: 13. Earning Before Interest and Tax | B15: 2809312 | C15: 3786318.6 | D15: 5053447.2 | E15: 5409735.4 | F15: 6471583.8 | G15: =G11+G14 -> 8590319.1 | H15: =H11+H14 -> 10763774 | I15: =I11+I14 -> 13506368 | J15: =J11+J14 -> 16056948 | K15: =K11+K14 -> 17996806 | M15: 11. Other expenses
A16: 14. Current corporate income tax expense | B16: 639743.6 | C16: 933836.7 | D16: 1248353.1 | E16: 1598413.8 | F16: 1632975.7 | G16: =G$2*G41 -> 2050995.5 | H16: =H$2*H41 -> 2600900.7 | I16: =I$2*I41 -> 2899306.2 | J16: =J$2*J41 -> 3267504.1 | K16: =K$2*K41 -> 3645614.8 | M16: 12. Other profit
A17: 15. Deferred corporate income tax expense | B17: -37328.7 | C17: -27827.2 | D17: -31146 | E17: -108551.1 | F17: -62818.6 | G17: =G$2*G42 -> -115561.96 | H17: =H$2*H42 -> -119294.7 | I17: =I$2*I42 -> -149139.15 | J17: =J$2*J42 -> -159821.33 | K17: =K$2*K42 -> -181698.33 | M17: 13. Earning Before Interest and Tax
A18: 16. Net profit after tax | B18: 2206897.1 | C18: 2880309.1 | D18: 3836240.1 | E18: 3919872.7 | F18: 4901426.7 | G18: =G15-G16-G17 -> 6654885.6 | H18: =H15-H16-H17 -> 8282167.8 | I18: =I15-I16-I17 -> 10756201 | J18: =J15-J16-J17 -> 12949266 | K18: =K15-K16-K17 -> 14532889 | M18: 14. Current corporate income tax expense
A19: 17. Equity holders of non-controlling interest | B19: 1217.5 | C19: 1584.9 | D19: 1970.5 | E19: 2104.9 | F19: 2557.4 | G19: =G2*G44 -> 3073.9247 | H19: =H2*H44 -> 3852.3457 | I19: =I2*I44 -> 4354.2033 | J19: =J2*J44 -> 4902.1681 | K19: =K2*K44 -> 5435.971 | M19: 15. Deferred corporate income tax expense
A20: 18. Net profit after tax of parent company | B20: 2205679.6 | C20: 2878724.1 | D20: 3834269.5 | E20: 3917767.8 | F20: 4898869.3 | G20: =G18-G19 -> 6651811.6 | H20: =H18-H19 -> 8278315.4 | I20: =I18-I19 -> 10751847 | J20: =J18-J19 -> 12944364 | K20: =K18-K19 -> 14527453 | M20: 16. Net profit after tax
M21: 17. Equity holders of non-controlling interest
A22: Share outstanding | E22: =690259427 -> 690259427 | F22: =710319805 -> 710319805 | G22: =DCF!B40*2 -> 1463709630 | H22: =G22 -> 1463709630 | I22: =H22 -> 1463709630 | J22: =I22 -> 1463709630 | K22: =J22 -> 1463709630 | M22: 18. Net profit after tax of parent company
A23: EPS | E23: =E20*10^6/E22 -> 5675.7904 | F23: =F20*10^6/F22 -> 6896.7094 | G23: =(G20*10^6)/G22 -> 4544.4885 | H23: =(H20*10^6)/H22 -> 5655.7088 | I23: =(I20*10^6)/I22 -> 7345.6147 | J23: =(J20*10^6)/J22 -> 8843.5324 | K23: =(K20*10^6)/K22 -> 9925.0923
A25: MWG Common-size Income Statement
A26: 1. Net revenue from sale of goods and services | B26: =B2/B$2 -> 1 | C26: =C2/C$2 -> 1 | D26: =D2/D$2 -> 1 | E26: =E2/E$2 -> 1 | F26: =F2/F$2 -> 1 | G26: =G2/G$2 -> 1 | H26: =H2/H$2 -> 1 | I26: =I2/I$2 -> 1 | ... K26: =K2/K$2 -> 1
A27: 2. Costs of goods sold | B27: =B3/B$2 -> 0.83204986 | C27: =C3/C$2 -> 0.82324568 | D27: =D3/D$2 -> 0.80926897 | E27: =E3/E$2 -> 0.77931483 | F27: =F3/F$2 -> 0.77527198 | G27: =G3/G$2 -> 0.77315537 | H27: =H3/H$2 -> 0.77468603 | I27: =I3/I$2 -> 0.77227404 | ... K27: =K3/K$2 -> 0.76874451
A28: 3. Gross profit | B28: =B4/B$2 -> 0.16795014 | C28: =C4/C$2 -> 0.17675432 | D28: =D4/D$2 -> 0.19073103 | E28: =E4/E$2 -> 0.22068517 | F28: =F4/F$2 -> 0.22472802 | G28: =G4/G$2 -> 0.22684463 | H28: =H4/H$2 -> 0.22531397 | I28: =I4/I$2 -> 0.22772596 | ... K28: =K4/K$2 -> 0.23125549
A29: 4. Income from financial activities | B29: =B5/B$2 -> 0.0037761613 | C29: =C5/C$2 -> 0.0039539827 | D29: =D5/D$2 -> 0.0061774658 | E29: =E5/E$2 -> 0.0073159919 | F29: =F5/F$2 -> 0.010474755 | G29: =G5/G$2 -> 0.008840829 | H29: =H5/H$2 -> 0.0075368062 | I29: =I5/I$2 -> 0.0069413031 | ... K29: =K5/K$2 -> 0.0062607361
A30: 5. Expenses from financial activities | B30: =B6/B$2 -> 0.0035316143 | C30: =C6/C$2 -> 0.0050461389 | D30: =D6/D$2 -> 0.0055763055 | E30: =E6/E$2 -> 0.005473729 | F30: =F6/F$2 -> 0.0058126074 | G30: =G6/G$2 -> 0.005915074 | H30: =H6/H$2 -> 0.0051277273 | I30: =I6/I$2 -> 0.0051886515 | ... K30: =K6/K$2 -> 0.0046607243
A31: Financial expenses (excluding interest expenses) | B31: =(B6-B7)/B2 -> 1.6344637e-05 | C31: =(C6-C7)/C2 -> 1.8100638e-06 | D31: =(D6-D7)/D2 -> 1.5836672e-05 | E31: =(E6-E7)/E2 -> 1.3607132e-06 | F31: =(F6-F7)/F2 -> 0.00032758719 | G31: =AVERAGE(B31:F31) -> 7.2587854e-05 | H31: =AVERAGE(C31:G31) -> 8.3836498e-05 | I31: =AVERAGE(D31:H31) -> 0.00010024178 | J31: =AVERAGE(E31:I31) -> 0.00011712281 | K31: =AVERAGE(F31:J31) -> 0.00014027523
A32: - In which: Interest expenses | B32: =B7/B$2 -> 0.0035152696 | C32: =C7/C$2 -> 0.0050443288 | D32: =D7/D$2 -> 0.0055604688 | E32: =E7/E$2 -> 0.0054723683 | F32: =F7/F$2 -> 0.0054850202 | G32: =G7/G2 -> 0.0058424861 | H32: =H7/H2 -> 0.0050438908 | I32: =I7/I2 -> 0.0050884097 | J32: =J7/J2 -> 0.0044226416 | K32: =K7/K2 -> 0.0045204491
A33: 6. Share in profits of associates | B33: =B8/B$2 -> 0 | C33: =C8/C$2 -> -2.4284445e-05 | D33: =D8/D$2 -> -3.399389e-05 | E33: =E8/E$2 -> -3.4150492e-05 | F33: =F8/F$2 -> -1.7977668e-05 | G33: =AVERAGE(D33:F33) -> -2.870735e-05 | H33: =AVERAGE(E33:G33) -> -2.694517e-05 | I33: =AVERAGE(F33:H33) -> -2.4543396e-05 | J33: =AVERAGE(G33:I33) -> -2.6731972e-05 | K33: =AVERAGE(H33:J33) -> -2.6073513e-05
A34: 7. Selling expenses | B34: =B9/B$2 -> 0.10577453 | C34: =C9/C$2 -> 0.11165229 | D34: =D9/D$2 -> 0.1217262 | E34: =E9/E$2 -> 0.14126542 | F34: =F9/F$2 -> 0.14569331 | G34: 0.14 | H34: =G34-0.3% -> 0.137 | I34: =H34-0.2% -> 0.135 | J34: =I34 -> 0.135 | K34: =J34 -> 0.135
A35: 8. General and administrative expenses | B35: =B10/B$2 -> 0.020281902 | C35: =C10/C$2 -> 0.020361645 | D35: =D10/D$2 -> 0.020296533 | E35: =E10/E$2 -> 0.031363949 | F35: =F10/F$2 -> 0.031095063 | G35: =F35+0.25% -> 0.033595063 | H35: =G35 -> 0.033595063 | I35: =H35-0.2% -> 0.031595063 | J35: =I35-0.1% -> 0.030595063 | K35: =J35 -> 0.030595063
A36: 9. Operating profit | B36: =B11/B$2 -> 0.042138258 | C36: =C11/C$2 -> 0.043623953 | D36: =D11/D$2 -> 0.049275465 | E36: =E11/E$2 -> 0.049863919 | F36: =F11/F$2 -> 0.05258382 | G36: =G11/G2 -> 0.056146611 | H36: =H11/H2 -> 0.057101041 | I36: =I11/I2 -> 0.062859005 | J36: =J11/J2 -> 0.066660793 | K36: =K11/K2 -> 0.067234365
A37: 10. Other income | B37: =B12/B$2 -> 0.00026657601 | C37: =C12/C$2 -> 0.00038412767 | D37: =D12/D$2 -> 0.00040672677 | E37: =E12/E$2 -> 0.00040086868 | F37: =F12/F$2 -> 0.00044627233 | G37: =AVERAGE(E37:F37) -> 0.0004235705 | H37: =AVERAGE(F37:G37) -> 0.00043492142 | I37: =AVERAGE(G37:H37) -> 0.00042924596 | J37: =AVERAGE(H37:I37) -> 0.00043208369 | K37: =AVERAGE(I37:J37) -> 0.00043066482
A38: 11. Other expenses | B38: =B13/B$2 -> 5.7528056e-05 | C38: =C13/C$2 -> 0.00024385235 | D38: =D13/D$2 -> 0.00022308264 | E38: =E13/E$2 -> 0.00042661352 | F38: =F13/F$2 -> 0.0003976639 | G38: =AVERAGE(E38:F38) -> 0.00041213871 | H38: =AVERAGE(F38:G38) -> 0.00040490131 | I38: =AVERAGE(G38:H38) -> 0.00040852001 | J38: =AVERAGE(H38:I38) -> 0.00040671066 | K38: =AVERAGE(I38:J38) -> 0.00040761533
A39: 12. Other profit | B39: =B14/B$2 -> 0.00020904946 | C39: =C14/C$2 -> 0.00014027648 | D39: =D14/D$2 -> 0.00018364511 | E39: =E14/E$2 -> -2.5744841e-05 | F39: =F14/F$2 -> 4.8608426e-05 | G39: =G14/G$2 -> 1.1431793e-05 | H39: =H14/H$2 -> 3.0020109e-05 | I39: =I14/I$2 -> 2.0725951e-05 | ... K39: =K14/K$2 -> 2.3049491e-05
A40: 13. Earning Before Interest and Tax | B40: =B15/B$2 -> 0.042347306 | C40: =C15/C$2 -> 0.043764229 | D40: =D15/D$2 -> 0.04945911 | E40: =E15/E$2 -> 0.049838174 | F40: =F15/F$2 -> 0.052632429 | G40: =G15/G$2 -> 0.056158042 | H40: =H15/H$2 -> 0.057131061 | I40: =I15/I$2 -> 0.062879731 | ... K40: =K15/K$2 -> 0.067257415
A41: 14. Current corporate income tax expense | B41: =B16/B$2 -> 0.0096434352 | C41: =C16/C$2 -> 0.010793768 | D41: =D16/D$2 -> 0.012217884 | E41: =E16/E$2 -> 0.014725679 | F41: =F16/F$2 -> 0.013280749 | G41: =AVERAGE(D41:F41) -> 0.013408104 | H41: =AVERAGE(E41:G41) -> 0.013804844 | I41: =AVERAGE(F41:H41) -> 0.013497899 | J41: =AVERAGE(G41:I41) -> 0.013570282 | K41: =AVERAGE(H41:J41) -> 0.013624342
...

Sheet BS
B1: MWG (Unit: Million VND) | C1: 2017 | D1: 2018 | E1: 2019 | F1: 2020 | G1: 2021 | H1: 2022F | I1: 2023F | J1: 2024F | K1: 2025F | L1: 2026F
B2: A. CURRENT ASSETS | C2: 18862861 | D2: 23371995 | E2: 35011897 | F2: 37317234 | G2: 51955258 | H2: =H3+H4+H8+H17+H20 -> 68268395 | I2: =I3+I4+I8+I17+I20 -> 77842032 | J2: =J3+J4+J8+J17+J20 -> 87916690 | K2: =K3+K4+K8+K17+K20 -> 96497049 | L2: =L3+L4+L8+L17+L20 -> 1.196949e+08
B3: I. Cash and Cash Equivalents | C3: 3410983.4 | D3: 3749550.3 | E3: 3115236.8 | F3: 7347857.4 | G3: 4142015.8 | H3: =CF!G31 -> 15191704 | I3: =CF!H31 -> 15373246 | J3: =CF!I31 -> 21499101 | K3: =CF!J31 -> 21515604 | L3: =CF!K31 -> 40291145
