Workbook

Sheet Lịch sử giá
A1: Ngày | B1: HPG | C1: HSG | D1: NKG | E1: KBC | F1: NLG | G1: DXG | H1: KDH | I1: GMD | J1: SBT | K1: DCM | L1: MSN | M1: MWG | N1: FPT | O1: VNM | P1: PNJ | Q1: REE | R1: VCB | S1: BID | T1: CTG | U1: PVD | V1: VNINDEX
A2: 42674 | B2: 40750 | C2: 40050 | D2: 15912.1 | E2: 17400 | F2: 21750 | G2: 5791.9 | H2: 11827.5 | I2: 27200 | J2: 23012.6 | K2: 11000 | L2: 65700 | M2: 145000 | N2: 43500 | O2: 142000 | P2: 68000 | Q2: 21250 | R2: 34507 | S2: 14613.4 | T2: 15366 | U2: 24250 | V2: 675.8
A3: 42704 | B3: 42100 | C3: 48600 | D3: 16263.7 | E3: 14300 | F3: 23000 | G3: 6790.5 | H3: 11325.3 | I3: 27200 | J3: 21262.6 | K3: 10750 | L3: 64100 | M3: 165000 | N3: 43350 | O3: 138000 | P3: 68900 | Q3: 22200 | R3: 33740 | S3: 14099.6 | T3: 14682 | U3: 21900 | V3: 665.07
A4: 42734 | B4: 43150 | C4: 50900 | D4: 15384.6 | E4: 13850 | F4: 22200 | G4: 6241.3 | H4: 11158 | I4: 27000 | J4: 21437.6 | K4: 10150 | L4: 64800 | M4: 156000 | N4: 44000 | O4: 125600 | P4: 66500 | Q4: 24650 | R4: 33980 | S4: 13085.9 | T4: 13725 | U4: 20700 | V4: 664.87
A5: 42760 | B5: 42300 | C5: 49700 | D5: 15516.5 | E5: 13650 | F5: 23000 | G5: 6715.6 | H5: 10990.6 | I5: 28300 | J5: 21262.6 | K5: 9670 | L5: 41250 | M5: 160000 | N5: 45100 | O5: 129000 | P5: 69000 | Q5: 25700 | R5: 37670 | S5: 15574.1 | T5: 17630 | U5: 21000 | V5: 697.28
A6: 42794 | B6: 40000 | C6: 47250 | D6: 16043.9 | E6: 14400 | F6: 22600 | G6: 8238.5 | H6: 12218 | I6: 34700 | J6: 21000.1 | K6: 10900 | L6: 41000 | M6: 167100 | N6: 45850 | O6: 131400 | P6: 75000 | Q6: 25100 | R6: 35849 | S6: 15159.4 | T6: 17345 | U6: 22200 | V6: 710.79
A7: 42825 | B7: 30550 | C7: 49500 | D7: 17802.2 | E7: 15000 | F7: 26500 | G7: 10285.6 | H7: 14142.7 | I7: 34600 | J7: 21612.6 | K7: 10450 | L7: 47050 | M7: 168300 | N7: 47300 | O7: 143300 | P7: 75800 | Q7: 27300 | R7: 35370 | S7: 16173.1 | T7: 17202 | U7: 20050 | V7: 722.31
A8: 42853 | B8: 29400 | C8: 48350 | D8: 18681.3 | E8: 14850 | F8: 28000 | G8: 10809.9 | H8: 13947.5 | I8: 34850 | J8: 23887.6 | K8: 13150 | L8: 44450 | M8: 167000 | N8: 46450 | O8: 148000 | P8: 87900 | Q8: 27850 | R8: 33645 | S8: 15297.6 | T8: 16489 | U8: 17700 | V8: 717.73
A9: 42886 | B9: 30400 | C9: 32800 | D9: 23202.2 | E9: 15800 | F9: 27900 | G9: 9882.1 | H9: 15509.6 | I9: 40000 | J9: 26293.9 | K9: 12900 | L9: 43200 | M9: 93500 | N9: 43000 | O9: 149700 | P9: 95300 | Q9: 31650 | R9: 34699 | S9: 17002.5 | T9: 17867 | U9: 15600 | V9: 737.82
A10: 42916 | B10: 32000 | C10: 32400 | D10: 22588 | E10: 16850 | F10: 28500 | G10: 9968.6 | H10: 15537.5 | I10: 43000 | J10: 30668.9 | K10: 14250 | L10: 42000 | M10: 102900 | N10: 46850 | O10: 157600 | P10: 101800 | Q10: 36900 | R10: 36904 | S10: 18799.5 | T10: 19245 | U10: 13850 | V10: 776.47
A11: 42947 | B11: 32300 | C11: 28000 | D11: 21700.9 | E11: 14650 | F11: 30350 | G11: 11005.7 | H11: 15621.2 | I11: 40500 | J11: 35393.9 | K11: 13600 | L11: 42800 | M11: 100500 | N11: 48350 | O11: 152600 | P11: 103900 | Q11: 37200 | R11: 36185 | S11: 20458.2 | T11: 19388 | U11: 13300 | V11: 783.55
A12: 42978 | B12: 35050 | C12: 29850 | D12: 22553.9 | E12: 15100 | F12: 28150 | G12: 11754.8 | H12: 15621.2 | I12: 42600 | J12: 28131.4 | K12: 13550 | L12: 47500 | M12: 109400 | N12: 48500 | O12: 148400 | P12: 107500 | Q12: 35150 | R12: 35562 | S12: 19685.7 | T12: 18105 | U12: 13800 | V12: 782.76
A13: 43007 | B13: 38900 | C13: 28600 | D13: 24055.2 | E13: 14600 | F13: 27050 | G13: 12100.6 | H13: 15993.1 | I13: 43750 | J13: 22750.1 | K13: 13650 | L13: 55100 | M13: 116300 | N13: 48750 | O13: 149200 | P13: 113800 | Q13: 35100 | R13: 36822 | S13: 18639.6 | T13: 18239 | U13: 14150 | V13: 804.42
... A63: 44530 | B63: 48950 | C63: 39550 | D63: 43000 | E63: 50000 | F63: 55800 | G63: 32700 | H63: 46450 | I63: 49800 | J63: 24500 | K63: 38000 | L63: 149200 | M63: 138900 | N63: 97100 | O63: 87600 | P63: 97900 | Q63: 70500 | R63: 98900 | S63: 44400 | T63: 33550 | U63: 27200 | V63: 1478.44

Sheet TSSL
A1: Ngày | B1: HPG | C1: HSG | D1: NKG | E1: KBC | F1: NLG | G1: DXG | H1: KDH | I1: GMD | J1: SBT | K1: DCM | L1: MSN | M1: MWG | N1: FPT | O1: VNM | P1: PNJ | Q1: REE | R1: VCB | S1: BID | T1: CTG | U1: PVD | V1: VNINDEX
A2: 42704 | B2: =LN('Lịch sử giá'!B3/'Lịch sử giá'!B2) -> 0.032591901 | C2: =LN('Lịch sử giá'!C3/'Lịch sử giá'!C2) -> 0.19349486 | D2: =LN('Lịch sử giá'!D3/'Lịch sử giá'!D2) -> 0.021855804 | E2: =LN('Lịch sử giá'!E3/'Lịch sử giá'!E2) -> -0.19621067 | F2: =LN('Lịch sử giá'!F3/'Lịch sử giá'!F2) -> 0.055880458 | G2: =LN('Lịch sử giá'!G3/'Lịch sử giá'!G2) -> 0.15906419 | H2: =LN('Lịch sử giá'!H3/'Lịch sử giá'!H2) -> -0.043388167 | I2: =LN('Lịch sử giá'!I3/'Lịch sử giá'!I2) -> 0 | ... V2: =LN('Lịch sử giá'!V3/'Lịch sử giá'!V2) -> -0.016004876
A3: 42734 | B3: =LN('Lịch sử giá'!B4/'Lịch sử giá'!B3) -> 0.024634677 | C3: =LN('Lịch sử giá'!C4/'Lịch sử giá'!C3) -> 0.046239393 | D3: =LN('Lịch sử giá'!D4/'Lịch sử giá'!D3) -> -0.055568621 | E3: =LN('Lịch sử giá'!E4/'Lịch sử giá'!E3) -> -0.031974305 | F3: =LN('Lịch sử giá'!F4/'Lịch sử giá'!F3) -> -0.035401927 | G3: =LN('Lịch sử giá'!G4/'Lịch sử giá'!G3) -> -0.084336083 | H3: =LN('Lịch sử giá'!H4/'Lịch sử giá'!H3) -> -0.014882432 | I3: =LN('Lịch sử giá'!I4/'Lịch sử giá'!I3) -> -0.0073801073 | ... V3: =LN('Lịch sử giá'!V4/'Lịch sử giá'!V3) -> -0.00030076545
A4: 42760 | B4: =LN('Lịch sử giá'!B5/'Lịch sử giá'!B4) -> -0.019895331 | C4: =LN('Lịch sử giá'!C5/'Lịch sử giá'!C4) -> -0.02385799 | D4: =LN('Lịch sử giá'!D5/'Lịch sử giá'!D4) -> 0.0085369648 | E4: =LN('Lịch sử giá'!E5/'Lịch sử giá'!E4) -> -0.014545711 | F4: =LN('Lịch sử giá'!F5/'Lịch sử giá'!F4) -> 0.035401927 | G4: =LN('Lịch sử giá'!G5/'Lịch sử giá'!G4) -> 0.073244684 | H4: =LN('Lịch sử giá'!H5/'Lịch sử giá'!H4) -> -0.015116367 | I4: =LN('Lịch sử giá'!I5/'Lịch sử giá'!I4) -> 0.047024939 | ... V4: =LN('Lịch sử giá'!V5/'Lịch sử giá'!V4) -> 0.047595519
A5: 42794 | B5: =LN('Lịch sử giá'!B6/'Lịch sử giá'!B5) -> -0.055907632 | C5: =LN('Lịch sử giá'!C6/'Lịch sử giá'!C5) -> -0.050552279 | D5: =LN('Lịch sử giá'!D6/'Lịch sử giá'!D5) -> 0.033424741 | E5: =LN('Lịch sử giá'!E6/'Lịch sử giá'!E5) -> 0.053488685 | F5: =LN('Lịch sử giá'!F6/'Lịch sử giá'!F5) -> -0.01754431 | G5: =LN('Lịch sử giá'!G6/'Lịch sử giá'!G5) -> 0.20438511 | H5: =LN('Lịch sử giá'!H6/'Lịch sử giá'!H5) -> 0.10586991 | I5: =LN('Lịch sử giá'!I6/'Lịch sử giá'!I5) -> 0.20387788 | ... V5: =LN('Lịch sử giá'!V6/'Lịch sử giá'!V5) -> 0.019189976
A6: 42825 | B6: =LN('Lịch sử giá'!B7/'Lịch sử giá'!B6) -> -0.26951477 | C6: =LN('Lịch sử giá'!C7/'Lịch sử giá'!C6) -> 0.046520016 | D6: =LN('Lịch sử giá'!D7/'Lịch sử giá'!D6) -> 0.10399333 | E6: =LN('Lịch sử giá'!E7/'Lịch sử giá'!E6) -> 0.040821995 | F6: =LN('Lịch sử giá'!F7/'Lịch sử giá'!F6) -> 0.15919483 | G6: =LN('Lịch sử giá'!G7/'Lịch sử giá'!G6) -> 0.22192657 | H6: =LN('Lịch sử giá'!H7/'Lịch sử giá'!H6) -> 0.14628832 | I6: =LN('Lịch sử giá'!I7/'Lịch sử giá'!I6) -> -0.0028860049 | ... V6: =LN('Lịch sử giá'!V7/'Lịch sử giá'!V6) -> 0.016077382
A7: 42853 | B7: =LN('Lịch sử giá'!B8/'Lịch sử giá'!B7) -> -0.038370011 | C7: =LN('Lịch sử giá'!C8/'Lịch sử giá'!C7) -> -0.023506448 | D7: =LN('Lịch sử giá'!D8/'Lịch sử giá'!D7) -> 0.048200978 | E7: =LN('Lịch sử giá'!E8/'Lịch sử giá'!E7) -> -0.010050336 | F7: =LN('Lịch sử giá'!F8/'Lịch sử giá'!F7) -> 0.055059777 | G7: =LN('Lịch sử giá'!G8/'Lịch sử giá'!G7) -> 0.049717522 | H7: =LN('Lịch sử giá'!H8/'Lịch sử giá'!H7) -> -0.013898309 | I7: =LN('Lịch sử giá'!I8/'Lịch sử giá'!I7) -> 0.0071994551 | ... V7: =LN('Lịch sử giá'!V8/'Lịch sử giá'!V7) -> -0.0063609559
A8: 42886 | B8: =LN('Lịch sử giá'!B9/'Lịch sử giá'!B8) -> 0.033447934 | C8: =LN('Lịch sử giá'!C9/'Lịch sử giá'!C8) -> -0.38803771 | D8: =LN('Lịch sử giá'!D9/'Lịch sử giá'!D8) -> 0.21672408 | E8: =LN('Lịch sử giá'!E9/'Lịch sử giá'!E8) -> 0.062010075 | F8: =LN('Lịch sử giá'!F9/'Lịch sử giá'!F8) -> -0.0035778213 | G8: =LN('Lịch sử giá'!G9/'Lịch sử giá'!G8) -> -0.089737341 | H8: =LN('Lịch sử giá'!H9/'Lịch sử giá'!H8) -> 0.10615891 | I8: =LN('Lịch sử giá'!I9/'Lịch sử giá'!I8) -> 0.13782632 | ... V8: =LN('Lịch sử giá'!V9/'Lịch sử giá'!V8) -> 0.027606439
A9: 42916 | B9: =LN('Lịch sử giá'!B10/'Lịch sử giá'!B9) -> 0.051293294 | C9: =LN('Lịch sử giá'!C10/'Lịch sử giá'!C9) -> -0.012270093 | D9: =LN('Lịch sử giá'!D10/'Lịch sử giá'!D9) -> -0.02682831 | E9: =LN('Lịch sử giá'!E10/'Lịch sử giá'!E9) -> 0.064340717 | F9: =LN('Lịch sử giá'!F10/'Lịch sử giá'!F9) -> 0.021277398 | G9: =LN('Lịch sử giá'!G10/'Lịch sử giá'!G9) -> 0.0087151131 | H9: =LN('Lịch sử giá'!H10/'Lịch sử giá'!H9) -> 0.0017972698 | I9: =LN('Lịch sử giá'!I10/'Lịch sử giá'!I9) -> 0.072320662 | ... V9: =LN('Lịch sử giá'!V10/'Lịch sử giá'!V9) -> 0.051058115
A10: 42947 | B10: =LN('Lịch sử giá'!B11/'Lịch sử giá'!B10) -> 0.0093313274 | C10: =LN('Lịch sử giá'!C11/'Lịch sử giá'!C10) -> -0.14595391 | D10: =LN('Lịch sử giá'!D11/'Lịch sử giá'!D10) -> -0.040065057 | E10: =LN('Lịch sử giá'!E11/'Lịch sử giá'!E10) -> -0.13991032 | F10: =LN('Lịch sử giá'!F11/'Lịch sử giá'!F10) -> 0.06289243 | G10: =LN('Lịch sử giá'!G11/'Lịch sử giá'!G10) -> 0.098973168 | H10: =LN('Lịch sử giá'!H11/'Lịch sử giá'!H10) -> 0.0053725092 | I10: =LN('Lịch sử giá'!I11/'Lịch sử giá'!I10) -> -0.059898142 | ... V10: =LN('Lịch sử giá'!V11/'Lịch sử giá'!V10) -> 0.009076869
A11: 42978 | B11: =LN('Lịch sử giá'!B12/'Lịch sử giá'!B11) -> 0.081708383 | C11: =LN('Lịch sử giá'!C12/'Lịch sử giá'!C11) -> 0.06398033 | D11: =LN('Lịch sử giá'!D12/'Lịch sử giá'!D11) -> 0.038554266 | E11: =LN('Lịch sử giá'!E12/'Lịch sử giá'!E11) -> 0.030254408 | F11: =LN('Lịch sử giá'!F12/'Lịch sử giá'!F11) -> -0.075249163 | G11: =LN('Lịch sử giá'!G12/'Lịch sử giá'!G11) -> 0.065848347 | H11: =LN('Lịch sử giá'!H12/'Lịch sử giá'!H11) -> 0 | I11: =LN('Lịch sử giá'!I12/'Lịch sử giá'!I11) -> 0.050552279 | ... V11: =LN('Lịch sử giá'!V12/'Lịch sử giá'!V11) -> -0.0010087404
A12: 43007 | B12: =LN('Lịch sử giá'!B13/'Lịch sử giá'!B12) -> 0.10421864 | C12: =LN('Lịch sử giá'!C13/'Lịch sử giá'!C12) -> -0.042778122 | D12: =LN('Lịch sử giá'!D13/'Lịch sử giá'!D12) -> 0.064443189 | E12: =LN('Lịch sử giá'!E13/'Lịch sử giá'!E12) -> -0.033673215 | F12: =LN('Lịch sử giá'!F13/'Lịch sử giá'!F12) -> -0.039860349 | G12: =LN('Lịch sử giá'!G13/'Lịch sử giá'!G12) -> 0.02899337 | H12: =LN('Lịch sử giá'!H13/'Lịch sử giá'!H12) -> 0.023528413 | I12: =LN('Lịch sử giá'!I13/'Lịch sử giá'!I12) -> 0.02663736 | ... V12: =LN('Lịch sử giá'!V13/'Lịch sử giá'!V12) -> 0.027295385
A13: 43039 | B13: =LN('Lịch sử giá'!B14/'Lịch sử giá'!B13) -> -0.050076338 | C13: =LN('Lịch sử giá'!C14/'Lịch sử giá'!C13) -> -0.21141194 | D13: =LN('Lịch sử giá'!D14/'Lịch sử giá'!D13) -> -0.017169909 | E13: =LN('Lịch sử giá'!E14/'Lịch sử giá'!E13) -> -0.12767772 | F13: =LN('Lịch sử giá'!F14/'Lịch sử giá'!F13) -> -0.011152532 | G13: =LN('Lịch sử giá'!G14/'Lịch sử giá'!G13) -> -0.11373668 | H13: =LN('Lịch sử giá'!H14/'Lịch sử giá'!H13) -> 0.078115502 | I13: =LN('Lịch sử giá'!I14/'Lịch sử giá'!I13) -> -0.077189639 | ... V13: =LN('Lịch sử giá'!V14/'Lịch sử giá'!V13) -> 0.040037022
... A62: 44530 | B62: =LN('Lịch sử giá'!B63/'Lịch sử giá'!B62) -> -0.15400475 | C62: =LN('Lịch sử giá'!C63/'Lịch sử giá'!C62) -> -0.18105653 | D62: =LN('Lịch sử giá'!D63/'Lịch sử giá'!D62) -> -0.23516404 | E62: =LN('Lịch sử giá'!E63/'Lịch sử giá'!E62) -> 0.027371197 | F62: =LN('Lịch sử giá'!F63/'Lịch sử giá'!F62) -> -0.038669141 | G62: =LN('Lịch sử giá'!G63/'Lịch sử giá'!G62) -> 0.3030907 | H62: =LN('Lịch sử giá'!H63/'Lịch sử giá'!H62) -> -0.093449167 | I62: =LN('Lịch sử giá'!I63/'Lịch sử giá'!I62) -> -0.048981387 | ... V62: =LN('Lịch sử giá'!V63/'Lịch sử giá'!V62) -> 0.023383474

Sheet Các chỉ tiêu cơ bản
B1: HPG | C1: HSG | D1: NKG | E1: KBC | F1: NLG | G1: DXG | H1: KDH | I1: GMD | J1: SBT | K1: DCM | L1: MSN | M1: MWG | N1: FPT | O1: VNM | P1: PNJ | Q1: REE | R1: VCB | S1: BID | T1: CTG | U1: PVD | V1: VNINDEX
A2: TSSL trung bình | B2: =AVERAGE(TSSL!B2:B62) -> 0.0030056316 | C2: =AVERAGE(TSSL!C2:C62) -> -0.00020595048 | D2: =AVERAGE(TSSL!D2:D62) -> 0.016297054 | E2: =AVERAGE(TSSL!E2:E62) -> 0.017304144 | F2: =AVERAGE(TSSL!F2:F62) -> 0.015445248 | G2: =AVERAGE(TSSL!G2:G62) -> 0.028375651 | H2: =AVERAGE(TSSL!H2:H62) -> 0.022425396 | I2: =AVERAGE(TSSL!I2:I62) -> 0.0099147215 | ... V2: =AVERAGE(TSSL!V2:V62) -> 0.012833534
A3: Phương sai | B3: =_xlfn.VAR.S(TSSL!B2:B62) -> 0.017620287 | C3: =_xlfn.VAR.S(TSSL!C2:C62) -> 0.034330205 | D3: =_xlfn.VAR.S(TSSL!D2:D62) -> 0.031569192 | E3: =_xlfn.VAR.S(TSSL!E2:E62) -> 0.011947508 | F3: =_xlfn.VAR.S(TSSL!F2:F62) -> 0.00707086 | G3: =_xlfn.VAR.S(TSSL!G2:G62) -> 0.0200106 | H3: =_xlfn.VAR.S(TSSL!H2:H62) -> 0.0070741526 | I3: =_xlfn.VAR.S(TSSL!I2:I62) -> 0.0095852321 | ... U3: =_xlfn.VAR.S(TSSL!U2:U62) -> 0.023473618
A4: Độ lệch chuẩn | B4: =SQRT(B3) -> 0.13274143 | C4: =SQRT(C3) -> 0.18528412 | D4: =SQRT(D3) -> 0.17767721 | E4: =SQRT(E3) -> 0.10930465 | F4: =SQRT(F3) -> 0.084088406 | G4: =SQRT(G3) -> 0.14145883 | H4: =SQRT(H3) -> 0.084107982 | I4: =SQRT(I3) -> 0.097904198 | ... U4: =SQRT(U3) -> 0.15321103
A5: Beta | B5: =SLOPE(TSSL!B2:B62,TSSL!$V$2:$V$62) -> 1.1796195 | C5: =SLOPE(TSSL!C2:C62,TSSL!$V$2:$V$62) -> 1.7697068 | D5: =SLOPE(TSSL!D2:D62,TSSL!$V$2:$V$62) -> 1.9193732 | E5: =SLOPE(TSSL!E2:E62,TSSL!$V$2:$V$62) -> 0.7387395 | F5: =SLOPE(TSSL!F2:F62,TSSL!$V$2:$V$62) -> 0.75869567 | G5: =SLOPE(TSSL!G2:G62,TSSL!$V$2:$V$62) -> 1.3722148 | H5: =SLOPE(TSSL!H2:H62,TSSL!$V$2:$V$62) -> 0.74791964 | I5: =SLOPE(TSSL!I2:I62,TSSL!$V$2:$V$62) -> 0.86788928 | ... P5: =SLOPE(TSSL!P2:P62,TSSL!$V$2:$V$62) -> 1.34106 | Q5: =SLOPE(TSSL!Q2:Q62,TSSL!V2:V62) -> 0.75171772 | R5: =SLOPE(TSSL!R2:R62,TSSL!$V$2:$V$62) -> 1.1024733 | S5: =SLOPE(TSSL!S2:S62,TSSL!$V$2:$V$62) -> 1.4021796 | T5: =SLOPE(TSSL!T2:T62,TSSL!$V$2:$V$62) -> 1.5004045 | U5: =SLOPE(TSSL!U2:U62,TSSL!$V$2:$V$62) -> 1.7890225

Sheet Các ma trận
A1: MA TRẬN HỆ SỐ TƯƠNG QUAN
B2: HPG | C2: HSG | D2: NKG | E2: KBC | F2: NLG | G2: DXG | H2: KDH | I2: GMD | J2: SBT | K2: DCM | L2: MSN | M2: MWG | N2: FPT | O2: VNM | P2: PNJ | Q2: REE | R2: VCB | S2: BID | T2: CTG | U2: PVD
A3: HPG | B3: 1 | C3: 0.4694537 | D3: 0.51353923 | E3: 0.30855887 | F3: 0.26797152 | G3: 0.41723573 | H3: 0.40615085 | I3: 0.40649189 | J3: 0.22606688 | K3: 0.26064095 | L3: 0.30184355 | M3: 0.28544933 | N3: 0.35094384 | O3: 0.18370806 | P3: 0.69535731 | Q3: 0.31756202 | R3: 0.47077774 | S3: 0.40424042 | T3: 0.45197765 | U3: 0.48111399
A4: HSG | B4: 0.4694537 | C4: 1 | D4: 0.71627986 | E4: 0.34085161 | F4: 0.40299915 | G4: 0.44210979 | H4: 0.42280467 | I4: 0.3898797 | J4: 0.35356647 | K4: 0.46598678 | L4: 0.24573683 | M4: 0.56350896 | N4: 0.53137362 | O4: 0.31672674 | P4: 0.34054172 | Q4: 0.41584319 | R4: 0.48469578 | S4: 0.40442149 | T4: 0.44263284 | U4: 0.62785483
A5: NKG | B5: 0.51353923 | C5: 0.71627986 | D5: 1 | E5: 0.42797782 | F5: 0.45771882 | G5: 0.46407615 | H5: 0.58326824 | I5: 0.54637856 | J5: 0.45101035 | K5: 0.52513547 | L5: 0.22096317 | M5: 0.40816906 | N5: 0.50176923 | O5: 0.32970995 | P5: 0.43358464 | Q5: 0.51856811 | R5: 0.48868606 | S5: 0.51231621 | T5: 0.50991915 | U5: 0.62120856
A6: KBC | B6: 0.30855887 | C6: 0.34085161 | D6: 0.42797782 | E6: 1 | F6: 0.3263476 | G6: 0.40120525 | H6: 0.3673916 | I6: 0.41651808 | J6: 0.39373474 | K6: 0.39350048 | L6: 0.063625879 | M6: 0.15913809 | N6: 0.30090716 | O6: 0.27193265 | P6: 0.31278092 | Q6: 0.42122535 | R6: 0.32092185 | S6: 0.22116449 | T6: 0.17973312 | U6: 0.53381464
A7: NLG | B7: 0.26797152 | C7: 0.40299915 | D7: 0.45771882 | E7: 0.3263476 | F7: 1 | G7: 0.50797046 | H7: 0.62666532 | I7: 0.28071432 | J7: 0.37986854 | K7: 0.32387524 | L7: 0.33170162 | M7: 0.27909253 | N7: 0.61492193 | O7: 0.42431668 | P7: 0.4533179 | Q7: 0.57587711 | R7: 0.33170126 | S7: 0.4450364 | T7: 0.34058572 | U7: 0.50782896
A8: DXG | B8: 0.41723573 | C8: 0.44210979 | D8: 0.46407615 | E8: 0.40120525 | F8: 0.50797046 | G8: 1 | H8: 0.56036249 | I8: 0.40158976 | J8: 0.37721132 | K8: 0.36632235 | L8: 0.31004774 | M8: 0.42781524 | N8: 0.61050685 | O8: 0.35672954 | P8: 0.49886261 | Q8: 0.43577149 | R8: 0.37338747 | S8: 0.49490835 | T8: 0.49363734 | U8: 0.58306942
A9: KDH | B9: 0.40615085 | C9: 0.42280467 | D9: 0.58326824 | E9: 0.3673916 | F9: 0.62666532 | G9: 0.56036249 | H9: 1 | I9: 0.42451764 | J9: 0.26210711 | K9: 0.21954819 | L9: 0.31705223 | M9: 0.35131466 | N9: 0.59747813 | O9: 0.24716523 | P9: 0.49252941 | Q9: 0.43874619 | R9: 0.33658883 | S9: 0.53238954 | T9: 0.33868979 | U9: 0.53334093
A10: GMD | B10: 0.40649189 | C10: 0.3898797 | D10: 0.54637856 | E10: 0.41651808 | F10: 0.28071432 | G10: 0.40158976 | H10: 0.42451764 | I10: 1 | J10: 0.43631717 | K10: 0.51894296 | L10: 0.12933049 | M10: 0.29084288 | N10: 0.47153754 | O10: 0.32507126 | P10: 0.31279163 | Q10: 0.53885849 | R10: 0.42023217 | S10: 0.31151089 | T10: 0.33804037 | U10: 0.55584729
A11: SBT | B11: 0.22606688 | C11: 0.35356647 | D11: 0.45101035 | E11: 0.39373474 | F11: 0.37986854 | G11: 0.37721132 | H11: 0.26210711 | I11: 0.43631717 | J11: 1 | K11: 0.44173904 | L11: 0.014158454 | M11: 0.15739267 | N11: 0.4445776 | O11: 0.28951647 | P11: 0.31724461 | Q11: 0.59689918 | R11: 0.39099155 | S11: 0.45144189 | T11: 0.4578145 | U11: 0.48289881
A12: DCM | B12: 0.26064095 | C12: 0.46598678 | D12: 0.52513547 | E12: 0.39350048 | F12: 0.32387524 | G12: 0.36632235 | H12: 0.21954819 | I12: 0.51894296 | J12: 0.44173904 | K12: 1 | L12: 0.21837298 | M12: 0.24666108 | N12: 0.34329195 | O12: 0.25541439 | P12: 0.2346779 | Q12: 0.33915768 | R12: 0.19989295 | S12: 0.22087705 | T12: 0.23931154 | U12: 0.46593231
A13: MSN | B13: 0.30184355 | C13: 0.24573683 | D13: 0.22096317 | E13: 0.063625879 | F13: 0.33170162 | G13: 0.31004774 | H13: 0.31705223 | I13: 0.12933049 | J13: 0.014158454 | K13: 0.21837298 | L13: 1 | M13: 0.13963315 | N13: 0.33110499 | O13: 0.2935205 | P13: 0.27151399 | Q13: 0.151754 | R13: 0.13193907 | S13: 0.12786007 | T13: 0.056664242 | U13: 0.23561491
A14: MWG | B14: 0.28544933 | C14: 0.56350896 | D14: 0.40816906 | E14: 0.15913809 | F14: 0.27909253 | G14: 0.42781524 | H14: 0.35131466 | I14: 0.29084288 | J14: 0.15739267 | K14: 0.24666108 | L14: 0.13963315 | M14: 1 | N14: 0.49659574 | O14: 0.19813734 | P14: 0.35375829 | Q14: 0.15257495 | R14: 0.37926947 | S14: 0.27752458 | T14: 0.29379767 | U14: 0.47276209
... A22: PVD | B22: 0.48111399 | C22: 0.62785483 | D22: 0.62120856 | E22: 0.53381464 | F22: 0.50782896 | G22: 0.58306942 | H22: 0.53334093 | I22: 0.55584729 | J22: 0.48289881 | K22: 0.46593231 | L22: 0.23561491 | M22: 0.47276209 | N22: 0.64788996 | O22: 0.45447885 | P22: 0.38832027 | Q22: 0.57308893 | R22: 0.60537908 | S22: 0.53484412 | T22: 0.5327051 | U22: 1
A24: MA TRẬN PHƯƠNG SAI - HIỆP PHƯƠNG SAI
A25: Cách 1 | B25: Dùng hàm MMULT
B26: HPG | C26: HSG | D26: NKG | E26: KBC | F26: NLG | G26: DXG | H26: KDH | I26: GMD | J26: SBT | K26: DCM | L26: MSN | M26: MWG | N26: FPT | O26: VNM | P26: PNJ | Q26: REE | R26: VCB | S26: BID | T26: CTG | U26: PVD
A27: HPG | B27: {=MMULT(TRANSPOSE(TSSL!B2:U62-'Các chỉ tiêu cơ bản'!B2:U2),TSSL!B2:U62-'Các chỉ tiêu cơ bản'!B2:U2)/61} -> 0.01733143 | C27: 0.011356876 | D27: 0.011913333 | E27: 0.0044035668 | F27: 0.0029420677 | G27: 0.0077061855 | H27: 0.004460181 | I27: 0.0051961432 | J27: 0.0035981619 | K27: 0.003908859 | L27: 0.0048341776 | M27: 0.0055966939 | N27: 0.0039041846 | O27: 0.0016974418 | P27: 0.013145934 | Q27: 0.0032729224 | R27: 0.0053817854 | S27: 0.0062980454 | T27: 0.0075520291 | U27: 0.0096242282
A28: HSG | B28: 0.011356876 | C28: 0.033767415 | D28: 0.023193916 | E28: 0.0067899037 | F28: 0.0061758944 | G28: 0.011397768 | H28: 0.0064809191 | I28: 0.0069565122 | J28: 0.0078550063 | K28: 0.0097546717 | L28: 0.0054934183 | M28: 0.0154218 | N28: 0.0082513387 | O28: 0.0040849158 | P28: 0.0089863936 | Q28: 0.0059823037 | R28: 0.0077341288 | S28: 0.0087949218 | T28: 0.010323383 | U28: 0.017531088
A29: NKG | B29: 0.011913333 | C29: 0.023193916 | D29: 0.031051664 | E29: 0.0081754764 | F29: 0.0067264828 | G29: 0.01147288 | H29: 0.0085735107 | I29: 0.0093486331 | J29: 0.0096084982 | K29: 0.010541537 | L29: 0.0047368086 | M29: 0.010711933 | N29: 0.0074717441 | O29: 0.0040777817 | P29: 0.010971918 | Q29: 0.0071538232 | R29: 0.0074776589 | S29: 0.01068389 | T29: 0.011404422 | U29: 0.016633384
A30: KBC | B30: 0.0044035668 | C30: 0.0067899037 | D30: 0.0081754764 | E30: 0.011751647 | F30: 0.0029503709 | G30: 0.0061017827 | H30: 0.0033222056 | I30: 0.0043842493 | J30: 0.0051603559 | K30: 0.004859424 | L30: 0.00083908638 | M30: 0.0025692646 | N30: 0.0027564962 | O30: 0.0020689986 | P30: 0.0048691799 | Q30: 0.003574817 | R30: 0.0030209386 | S30: 0.0028373545 | T30: 0.0024729024 | U30: 0.0087930709
A31: NLG | B31: 0.0029420677 | C31: 0.0061758944 | D31: 0.0067264828 | E31: 0.0029503709 | F31: 0.0069549443 | G31: 0.0059432781 | H31: 0.0043594371 | I31: 0.0022731255 | J31: 0.00383007 | K31: 0.0030769096 | L31: 0.0033652547 | M31: 0.0034664135 | N31: 0.0043335352 | O31: 0.0024836272 | P31: 0.0054289508 | Q31: 0.0037598161 | R31: 0.0024020786 | S31: 0.004392292 | T31: 0.0036049792 | U31: 0.006435244
A32: DXG | B32: 0.0077061855 | C32: 0.011397768 | D32: 0.01147288 | E32: 0.0061017827 | F32: 0.0059432781 | G32: 0.019682558 | H32: 0.0065577936 | I32: 0.0054706059 | J32: 0.0063981151 | K32: 0.0058545612 | L32: 0.0052916712 | M32: 0.0089388644 | N32: 0.0072378042 | O32: 0.0035126051 | P32: 0.010050506 | Q32: 0.0047861857 | R32: 0.0045487678 | S32: 0.0082170211 | T32: 0.0087897854 | U32: 0.012429732
A33: KDH | B33: 0.004460181 | C33: 0.0064809191 | D33: 0.0085735107 | E33: 0.0033222056 | F33: 0.0043594371 | G33: 0.0065577936 | H33: 0.0069581829 | I33: 0.0034383944 | J33: 0.0026433416 | K33: 0.0020862577 | L33: 0.0032173792 | M33: 0.0043644499 | N33: 0.0042115839 | O33: 0.0014470541 | P33: 0.0058999224 | Q33: 0.0028651755 | R33: 0.0024380403 | S33: 0.0052556481 | T33: 0.0035857459 | U33: 0.0067601069
A34: GMD | B34: 0.0051961432 | C34: 0.0069565122 | D34: 0.0093486331 | E34: 0.0043842493 | F34: 0.0022731255 | G34: 0.0054706059 | H34: 0.0034383944 | I34: 0.0094280971 | J34: 0.0051220155 | K34: 0.0057401311 | L34: 0.0015276943 | M34: 0.0042058695 | N34: 0.0038690453 | O34: 0.0022153384 | P34: 0.0043614748 | Q34: 0.0040961581 | R34: 0.0035431911 | S34: 0.0035795968 | T34: 0.0041659119 | U34: 0.008201027
A35: SBT | B35: 0.0035981619 | C35: 0.0078550063 | D35: 0.0096084982 | E35: 0.0051603559 | F35: 0.00383007 | G35: 0.0063981151 | H35: 0.0026433416 | I35: 0.0051220155 | J35: 0.014616828 | K35: 0.0060839061 | L35: 0.00020824084 | M35: 0.0028339775 | N35: 0.0045420264 | O35: 0.0024566841 | P35: 0.0055079124 | Q35: 0.0056495974 | R35: 0.0041047545 | S35: 0.0064591782 | T35: 0.0070249882 | U35: 0.0088712215
A36: DCM | B36: 0.003908859 | C36: 0.0097546717 | D36: 0.010541537 | E36: 0.004859424 | F36: 0.0030769096 | G36: 0.0058545612 | H36: 0.0020862577 | I36: 0.0057401311 | J36: 0.0060839061 | K36: 0.01297718 | L36: 0.0030263042 | M36: 0.0041848135 | N36: 0.0033046791 | O36: 0.0020421376 | P36: 0.0038390925 | Q36: 0.0030246963 | R36: 0.0019773379 | S36: 0.0029777594 | T36: 0.0034600574 | U36: 0.0080651735
A37: MSN | B37: 0.0048341776 | C37: 0.0054934183 | D37: 0.0047368086 | E37: 0.00083908638 | F37: 0.0033652547 | G37: 0.0052916712 | H37: 0.0032173792 | I37: 0.0015276943 | J37: 0.00020824084 | K37: 0.0030263042 | L37: 0.014799499 | M37: 0.0025298652 | N37: 0.0034038056 | O37: 0.0025061751 | P37: 0.0047433146 | Q37: 0.0014452854 | R37: 0.0013937671 | S37: 0.001840803 | T37: 0.0008749074 | U37: 0.0043553896
A38: MWG | B38: 0.0055966939 | C38: 0.0154218 | D38: 0.010711933 | E38: 0.0025692646 | F38: 0.0034664135 | G38: 0.0089388644 | H38: 0.0043644499 | I38: 0.0042058695 | J38: 0.0028339775 | K38: 0.0041848135 | L38: 0.0025298652 | M38: 0.022180465 | N38: 0.0062497671 | O38: 0.0020711003 | P38: 0.0075658576 | Q38: 0.0017789286 | R38: 0.0049048584 | S38: 0.0048914276 | T38: 0.0055534539 | U38: 0.010698643
A39: FPT | B39: 0.0039041846 | C39: 0.0082513387 | D39: 0.0074717441 | E39: 0.0027564962 | F39: 0.0043335352 | G39: 0.0072378042 | H39: 0.0042115839 | I39: 0.0038690453 | J39: 0.0045420264 | K39: 0.0033046791 | L39: 0.0034038056 | M39: 0.0062497671 | N39: 0.0071408686 | O39: 0.0022886456 | P39: 0.0060147777 | Q39: 0.0038122598 | R39: 0.0029339476 | S39: 0.0057781375 | T39: 0.0054642646 | U39: 0.0083191221
... A46: PVD | B46: 0.0096242282 | C46: 0.017531088 | D46: 0.016633384 | E46: 0.0087930709 | F46: 0.006435244 | G46: 0.012429732 | H46: 0.0067601069 | I46: 0.008201027 | J46: 0.0088712215 | K46: 0.0080651735 | L46: 0.0043553896 | M46: 0.010698643 | N46: 0.0083191221 | O46: 0.004846898 | P46: 0.0084733862 | Q46: 0.0068173047 | R46: 0.0079876935 | S46: 0.0096178234 | T46: 0.010273468 | U46: 0.023088805
A47: Cách 2 | B47: Dùng Covariance / Data analysis
B48: HPG | C48: HSG | D48: NKG | E48: KBC | F48: NLG | G48: DXG | H48: KDH | I48: GMD | J48: SBT | K48: DCM | L48: MSN | M48: MWG | N48: FPT | O48: VNM | P48: PNJ | Q48: REE | R48: VCB | S48: BID | T48: CTG | U48: PVD
A49: HPG | B49: 0.01733143 | C49: 0.011356876 | D49: 0.011913333 | E49: 0.0044035668 | F49: 0.0029420677 | G49: 0.0077061855 | H49: 0.004460181 | I49: 0.0051961432 | J49: 0.0035981619 | K49: 0.003908859 | L49: 0.0048341776 | M49: 0.0055966939 | N49: 0.0039041846 | O49: 0.0016974418 | P49: 0.013145934 | Q49: 0.0032729224 | R49: 0.0053817854 | S49: 0.0062980454 | T49: 0.0075520291 | U49: 0.0096242282
A50: HSG | B50: 0.011356876 | C50: 0.033767415 | D50: 0.023193916 | E50: 0.0067899037 | F50: 0.0061758944 | G50: 0.011397768 | H50: 0.0064809191 | I50: 0.0069565122 | J50: 0.0078550063 | K50: 0.0097546717 | L50: 0.0054934183 | M50: 0.0154218 | N50: 0.0082513387 | O50: 0.0040849158 | P50: 0.0089863936 | Q50: 0.0059823037 | R50: 0.0077341288 | S50: 0.0087949218 | T50: 0.010323383 | U50: 0.017531088
A51: NKG | B51: 0.011913333 | C51: 0.023193916 | D51: 0.031051664 | E51: 0.0081754764 | F51: 0.0067264828 | G51: 0.01147288 | H51: 0.0085735107 | I51: 0.0093486331 | J51: 0.0096084982 | K51: 0.010541537 | L51: 0.0047368086 | M51: 0.010711933 | N51: 0.0074717441 | O51: 0.0040777817 | P51: 0.010971918 | Q51: 0.0071538232 | R51: 0.0074776589 | S51: 0.01068389 | T51: 0.011404422 | U51: 0.016633384
A52: KBC | B52: 0.0044035668 | C52: 0.0067899037 | D52: 0.0081754764 | E52: 0.011751647 | F52: 0.0029503709 | G52: 0.0061017827 | H52: 0.0033222056 | I52: 0.0043842493 | J52: 0.0051603559 | K52: 0.004859424 | L52: 0.00083908638 | M52: 0.0025692646 | N52: 0.0027564962 | O52: 0.0020689986 | P52: 0.0048691799 | Q52: 0.003574817 | R52: 0.0030209386 | S52: 0.0028373545 | T52: 0.0024729024 | U52: 0.0087930709
A53: NLG | B53: 0.0029420677 | C53: 0.0061758944 | D53: 0.0067264828 | E53: 0.0029503709 | F53: 0.0069549443 | G53: 0.0059432781 | H53: 0.0043594371 | I53: 0.0022731255 | J53: 0.00383007 | K53: 0.0030769096 | L53: 0.0033652547 | M53: 0.0034664135 | N53: 0.0043335352 | O53: 0.0024836272 | P53: 0.0054289508 | Q53: 0.0037598161 | R53: 0.0024020786 | S53: 0.004392292 | T53: 0.0036049792 | U53: 0.006435244
A54: DXG | B54: 0.0077061855 | C54: 0.011397768 | D54: 0.01147288 | E54: 0.0061017827 | F54: 0.0059432781 | G54: 0.019682558 | H54: 0.0065577936 | I54: 0.0054706059 | J54: 0.0063981151 | K54: 0.0058545612 | L54: 0.0052916712 | M54: 0.0089388644 | N54: 0.0072378042 | O54: 0.0035126051 | P54: 0.010050506 | Q54: 0.0047861857 | R54: 0.0045487678 | S54: 0.0082170211 | T54: 0.0087897854 | U54: 0.012429732
...

Sheet Mô hình CAPM & SML
A1: MÔ HÌNH CAPM
B2: HPG | C2: HSG | D2: NKG | E2: KBC | F2: NLG | G2: DXG | H2: KDH | I2: GMD | J2: SBT | K2: DCM | L2: MSN | M2: MWG | N2: FPT | O2: VNM | P2: PNJ | Q2: REE | R2: VCB | S2: BID | T2: CTG | U2: PVD | V2: VNINDEX
A3: TSSL trung bình | B3: =AVERAGE(TSSL!B2:B62) -> 0.0030056316 | C3: =AVERAGE(TSSL!C2:C62) -> -0.00020595048 | D3: =AVERAGE(TSSL!D2:D62) -> 0.016297054 | E3: =AVERAGE(TSSL!E2:E62) -> 0.017304144 | F3: =AVERAGE(TSSL!F2:F62) -> 0.015445248 | G3: =AVERAGE(TSSL!G2:G62) -> 0.028375651 | H3: =AVERAGE(TSSL!H2:H62) -> 0.022425396 | I3: =AVERAGE(TSSL!I2:I62) -> 0.0099147215 | ... V3: =AVERAGE(TSSL!V2:V62) -> 0.012833534
A4: Beta | B4: =SLOPE(TSSL!B2:B62,TSSL!$V$2:$V$62) -> 1.1796195 | C4: =SLOPE(TSSL!C2:C62,TSSL!$V$2:$V$62) -> 1.7697068 | D4: =SLOPE(TSSL!D2:D62,TSSL!$V$2:$V$62) -> 1.9193732 | E4: =SLOPE(TSSL!E2:E62,TSSL!$V$2:$V$62) -> 0.7387395 | F4: =SLOPE(TSSL!F2:F62,TSSL!$V$2:$V$62) -> 0.75869567 | G4: =SLOPE(TSSL!G2:G62,TSSL!$V$2:$V$62) -> 1.3722148 | H4: =SLOPE(TSSL!H2:H62,TSSL!$V$2:$V$62) -> 0.74791964 | I4: =SLOPE(TSSL!I2:I62,TSSL!$V$2:$V$62) -> 0.86788928 | ... V4: =SLOPE(TSSL!V2:V62,TSSL!$V$2:$V$62) -> 1
A5: Alpha | B5: =INTERCEPT(TSSL!B2:B62,TSSL!$V$2:$V$62) -> -0.012133056 | C5: =INTERCEPT(TSSL!C2:C62,TSSL!$V$2:$V$62) -> -0.022917543 | D5: =INTERCEPT(TSSL!D2:D62,TSSL!$V$2:$V$62) -> -0.0083352871 | E5: =INTERCEPT(TSSL!E2:E62,TSSL!$V$2:$V$62) -> 0.0078235057 | F5: =INTERCEPT(TSSL!F2:F62,TSSL!$V$2:$V$62) -> 0.005708501 | G5: =INTERCEPT(TSSL!G2:G62,TSSL!$V$2:$V$62) -> 0.010765285 | H5: =INTERCEPT(TSSL!H2:H62,TSSL!$V$2:$V$62) -> 0.012826943 | I5: =INTERCEPT(TSSL!I2:I62,TSSL!$V$2:$V$62) -> -0.0012233652 | ... V5: =INTERCEPT(TSSL!V2:V62,TSSL!$V$2:$V$62) -> 0
A6: R-squared | B6: =RSQ(TSSL!B2:B62,TSSL!$V$2:$V$62) -> 0.3419034 | C6: =RSQ(TSSL!C2:C62,TSSL!$V$2:$V$62) -> 0.39496513 | D6: =RSQ(TSSL!D2:D62,TSSL!$V$2:$V$62) -> 0.50522855 | E6: =RSQ(TSSL!E2:E62,TSSL!$V$2:$V$62) -> 0.19775972 | F6: =RSQ(TSSL!F2:F62,TSSL!$V$2:$V$62) -> 0.35244835 | G6: =RSQ(TSSL!G2:G62,TSSL!$V$2:$V$62) -> 0.40739585 | H6: =RSQ(TSSL!H2:H62,TSSL!$V$2:$V$62) -> 0.34234813 | I6: =RSQ(TSSL!I2:I62,TSSL!$V$2:$V$62) -> 0.34021898 | ... V6: =RSQ(TSSL!V2:V62,TSSL!$V$2:$V$62) -> 1
A9: Mã chứng khoán | B9: Beta | C9: TSSL trung bình | F9: KIỂM ĐỊNH MÔ HÌNH CAPM
A10: HPG | B10: =B4 -> 1.1796195 | C10: =B3 -> 0.0030056316 | F10: SUMMARY OUTPUT
A11: HSG | B11: =C4 -> 1.7697068 | C11: =C3 -> -0.00020595048
A12: NKG | B12: =D4 -> 1.9193732 | C12: =D3 -> 0.016297054 | F12: Regression Statistics
A13: KBC | B13: =E4 -> 0.7387395 | C13: =E3 -> 0.017304144 | F13: Multiple R | G13: 0.12836679
A14: NLG | B14: =F4 -> 0.75869567 | C14: =F3 -> 0.015445248 | F14: R Square | G14: 0.016478033
A15: DXG | B15: =G4 -> 1.3722148 | C15: =G3 -> 0.028375651 | F15: Adjusted R Square | G15: -0.038162076
A16: KDH | B16: =H4 -> 0.74791964 | C16: =H3 -> 0.022425396 | F16: Standard Error | G16: 0.0095741896
A17: GMD | B17: =I4 -> 0.86788928 | C17: =I3 -> 0.0099147215 | F17: Observations | G17: 20
A18: SBT | B18: =J4 -> 1.02129 | C18: =J3 -> 0.0010267414
A19: DCM | B19: =K4 -> 0.83974117 | C19: =K3 -> 0.020322801 | F19: ANOVA
A20: MSN | B20: =L4 -> 0.65359052 | C20: =L3 -> 0.013445717 | G20: df | H20: SS | I20: MS | J20: F | K20: Significance F
A21: MWG | B21: =M4 -> 1.0790944 | C21: =M3 -> -0.00070458185 | F21: Regression | G21: 1 | H21: 2.7643808e-05 | I21: 2.7643808e-05 | J21: 0.30157395 | K21: 0.58964577
A22: FPT | B22: =N4 -> 0.88562792 | C22: =N3 -> 0.013163614 | F22: Residual | G22: 18 | H22: 0.0016499719 | I22: 9.1665106e-05
A23: VNM | B23: =O4 -> 0.66771797 | C23: =O3 -> -0.0079187879 | F23: Total | G23: 19 | H23: 0.0016776157
A24: PNJ | B24: =P4 -> 1.34106 | C24: =P3 -> 0.0059744073
A25: REE | B25: =Q4 -> 0.75171772 | C25: =Q3 -> 0.019659931 | G25: Coefficients | H25: Standard Error | I25: t Stat | J25: P-value | K25: Lower 95% | L25: Upper 95% | M25: Lower 95,0% | N25: Upper 95,0%
A26: VCB | B26: =R4 -> 1.1024733 | C26: =R3 -> 0.017261427 | F26: Intercept | G26: 0.01476593 | H26: 0.0065186558 | I26: 2.2651802 | J26: 0.036076874 | K26: 0.0010707424 | L26: 0.028461118 | M26: 0.0010707424 | N26: 0.028461118
A27: BID | B27: =S4 -> 1.4021796 | C27: =S3 -> 0.018218042 | F27: Beta | G27: -0.0030205415 | H27: 0.0055003192 | I27: -0.54915749 | J27: 0.58964577 | K27: -0.014576283 | L27: 0.0085352004 | M27: -0.014576283 | N27: 0.0085352004
A28: CTG | B28: =T4 -> 1.5004045 | C28: =T3 -> 0.012801305
A29: PVD | B29: =U4 -> 1.7890225 | C29: =U3 -> 0.001881973

Sheet DM tối ưu hóa
B1: HPG | C1: HSG | D1: NKG | E1: KBC | F1: NLG | G1: DXG | H1: KDH | I1: GMD | J1: SBT | K1: DCM | L1: MSN | M1: MWG | N1: FPT | O1: VNM | P1: PNJ | Q1: REE | R1: VCB | S1: BID | T1: CTG | U1: PVD
A2: Tỷ suất sinh lợi trung bình | B2: =AVERAGE(TSSL!B2:B62) -> 0.0030056316 | C2: =AVERAGE(TSSL!C2:C62) -> -0.00020595048 | D2: =AVERAGE(TSSL!D2:D62) -> 0.016297054 | E2: =AVERAGE(TSSL!E2:E62) -> 0.017304144 | F2: =AVERAGE(TSSL!F2:F62) -> 0.015445248 | G2: =AVERAGE(TSSL!G2:G62) -> 0.028375651 | H2: =AVERAGE(TSSL!H2:H62) -> 0.022425396 | I2: =AVERAGE(TSSL!I2:I62) -> 0.0099147215 | ... U2: =AVERAGE(TSSL!U2:U62) -> 0.001881973
A3: MA TRẬN PHƯƠNG SAI - HIỆP PHƯƠNG SAI
B4: HPG | C4: HSG | D4: NKG | E4: KBC | F4: NLG | G4: DXG | H4: KDH | I4: GMD | J4: SBT | K4: DCM | L4: MSN | M4: MWG | N4: FPT | O4: VNM | P4: PNJ | Q4: REE | R4: VCB | S4: BID | T4: CTG | U4: PVD
A5: HPG | B5: {=MMULT(TRANSPOSE(TSSL!B2:U62-'Các chỉ tiêu cơ bản'!B2:U2),TSSL!B2:U62-'Các chỉ tiêu cơ bản'!B2:U2)/61} -> 0.01733143 | C5: 0.011356876 | D5: 0.011913333 | E5: 0.0044035668 | F5: 0.0029420677 | G5: 0.0077061855 | H5: 0.004460181 | I5: 0.0051961432 | J5: 0.0035981619 | K5: 0.003908859 | L5: 0.0048341776 | M5: 0.0055966939 | N5: 0.0039041846 | O5: 0.0016974418 | P5: 0.013145934 | Q5: 0.0032729224 | R5: 0.0053817854 | S5: 0.0062980454 | T5: 0.0075520291 | U5: 0.0096242282
A6: HSG | B6: 0.011356876 | C6: 0.033767415 | D6: 0.023193916 | E6: 0.0067899037 | F6: 0.0061758944 | G6: 0.011397768 | H6: 0.0064809191 | I6: 0.0069565122 | J6: 0.0078550063 | K6: 0.0097546717 | L6: 0.0054934183 | M6: 0.0154218 | N6: 0.0082513387 | O6: 0.0040849158 | P6: 0.0089863936 | Q6: 0.0059823037 | R6: 0.0077341288 | S6: 0.0087949218 | T6: 0.010323383 | U6: 0.017531088
A7: NKG | B7: 0.011913333 | C7: 0.023193916 | D7: 0.031051664 | E7: 0.0081754764 | F7: 0.0067264828 | G7: 0.01147288 | H7: 0.0085735107 | I7: 0.0093486331 | J7: 0.0096084982 | K7: 0.010541537 | L7: 0.0047368086 | M7: 0.010711933 | N7: 0.0074717441 | O7: 0.0040777817 | P7: 0.010971918 | Q7: 0.0071538232 | R7: 0.0074776589 | S7: 0.01068389 | T7: 0.011404422 | U7: 0.016633384
A8: KBC | B8: 0.0044035668 | C8: 0.0067899037 | D8: 0.0081754764 | E8: 0.011751647 | F8: 0.0029503709 | G8: 0.0061017827 | H8: 0.0033222056 | I8: 0.0043842493 | J8: 0.0051603559 | K8: 0.004859424 | L8: 0.00083908638 | M8: 0.0025692646 | N8: 0.0027564962 | O8: 0.0020689986 | P8: 0.0048691799 | Q8: 0.003574817 | R8: 0.0030209386 | S8: 0.0028373545 | T8: 0.0024729024 | U8: 0.0087930709
A9: NLG | B9: 0.0029420677 | C9: 0.0061758944 | D9: 0.0067264828 | E9: 0.0029503709 | F9: 0.0069549443 | G9: 0.0059432781 | H9: 0.0043594371 | I9: 0.0022731255 | J9: 0.00383007 | K9: 0.0030769096 | L9: 0.0033652547 | M9: 0.0034664135 | N9: 0.0043335352 | O9: 0.0024836272 | P9: 0.0054289508 | Q9: 0.0037598161 | R9: 0.0024020786 | S9: 0.004392292 | T9: 0.0036049792 | U9: 0.006435244
A10: DXG | B10: 0.0077061855 | C10: 0.011397768 | D10: 0.01147288 | E10: 0.0061017827 | F10: 0.0059432781 | G10: 0.019682558 | H10: 0.0065577936 | I10: 0.0054706059 | J10: 0.0063981151 | K10: 0.0058545612 | L10: 0.0052916712 | M10: 0.0089388644 | N10: 0.0072378042 | O10: 0.0035126051 | P10: 0.010050506 | Q10: 0.0047861857 | R10: 0.0045487678 | S10: 0.0082170211 | T10: 0.0087897854 | U10: 0.012429732
A11: KDH | B11: 0.004460181 | C11: 0.0064809191 | D11: 0.0085735107 | E11: 0.0033222056 | F11: 0.0043594371 | G11: 0.0065577936 | H11: 0.0069581829 | I11: 0.0034383944 | J11: 0.0026433416 | K11: 0.0020862577 | L11: 0.0032173792 | M11: 0.0043644499 | N11: 0.0042115839 | O11: 0.0014470541 | P11: 0.0058999224 | Q11: 0.0028651755 | R11: 0.0024380403 | S11: 0.0052556481 | T11: 0.0035857459 | U11: 0.0067601069
A12: GMD | B12: 0.0051961432 | C12: 0.0069565122 | D12: 0.0093486331 | E12: 0.0043842493 | F12: 0.0022731255 | G12: 0.0054706059 | H12: 0.0034383944 | I12: 0.0094280971 | J12: 0.0051220155 | K12: 0.0057401311 | L12: 0.0015276943 | M12: 0.0042058695 | N12: 0.0038690453 | O12: 0.0022153384 | P12: 0.0043614748 | Q12: 0.0040961581 | R12: 0.0035431911 | S12: 0.0035795968 | T12: 0.0041659119 | U12: 0.008201027
A13: SBT | B13: 0.0035981619 | C13: 0.0078550063 | D13: 0.0096084982 | E13: 0.0051603559 | F13: 0.00383007 | G13: 0.0063981151 | H13: 0.0026433416 | I13: 0.0051220155 | J13: 0.014616828 | K13: 0.0060839061 | L13: 0.00020824084 | M13: 0.0028339775 | N13: 0.0045420264 | O13: 0.0024566841 | P13: 0.0055079124 | Q13: 0.0056495974 | R13: 0.0041047545 | S13: 0.0064591782 | T13: 0.0070249882 | U13: 0.0088712215
A14: DCM | B14: 0.003908859 | C14: 0.0097546717 | D14: 0.010541537 | E14: 0.004859424 | F14: 0.0030769096 | G14: 0.0058545612 | H14: 0.0020862577 | I14: 0.0057401311 | J14: 0.0060839061 | K14: 0.01297718 | L14: 0.0030263042 | M14: 0.0041848135 | N14: 0.0033046791 | O14: 0.0020421376 | P14: 0.0038390925 | Q14: 0.0030246963 | R14: 0.0019773379 | S14: 0.0029777594 | T14: 0.0034600574 | U14: 0.0080651735
A15: MSN | B15: 0.0048341776 | C15: 0.0054934183 | D15: 0.0047368086 | E15: 0.00083908638 | F15: 0.0033652547 | G15: 0.0052916712 | H15: 0.0032173792 | I15: 0.0015276943 | J15: 0.00020824084 | K15: 0.0030263042 | L15: 0.014799499 | M15: 0.0025298652 | N15: 0.0034038056 | O15: 0.0025061751 | P15: 0.0047433146 | Q15: 0.0014452854 | R15: 0.0013937671 | S15: 0.001840803 | T15: 0.0008749074 | U15: 0.0043553896
A16: MWG | B16: 0.0055966939 | C16: 0.0154218 | D16: 0.010711933 | E16: 0.0025692646 | F16: 0.0034664135 | G16: 0.0089388644 | H16: 0.0043644499 | I16: 0.0042058695 | J16: 0.0028339775 | K16: 0.0041848135 | L16: 0.0025298652 | M16: 0.022180465 | N16: 0.0062497671 | O16: 0.0020711003 | P16: 0.0075658576 | Q16: 0.0017789286 | R16: 0.0049048584 | S16: 0.0048914276 | T16: 0.0055534539 | U16: 0.010698643
A17: FPT | B17: 0.0039041846 | C17: 0.0082513387 | D17: 0.0074717441 | E17: 0.0027564962 | F17: 0.0043335352 | G17: 0.0072378042 | H17: 0.0042115839 | I17: 0.0038690453 | J17: 0.0045420264 | K17: 0.0033046791 | L17: 0.0034038056 | M17: 0.0062497671 | N17: 0.0071408686 | O17: 0.0022886456 | P17: 0.0060147777 | Q17: 0.0038122598 | R17: 0.0029339476 | S17: 0.0057781375 | T17: 0.0054642646 | U17: 0.0083191221
... A24: PVD | B24: 0.0096242282 | C24: 0.017531088 | D24: 0.016633384 | E24: 0.0087930709 | F24: 0.006435244 | G24: 0.012429732 | H24: 0.0067601069 | I24: 0.008201027 | J24: 0.0088712215 | K24: 0.0080651735 | L24: 0.0043553896 | M24: 0.010698643 | N24: 0.0083191221 | O24: 0.004846898 | P24: 0.0084733862 | Q24: 0.0068173047 | R24: 0.0079876935 | S24: 0.0096178234 | T24: 0.010273468 | U24: 0.023088805
A25: Mã chứng khoán | B25: HPG | C25: HSG | D25: NKG | E25: KBC | F25: NLG | G25: DXG | H25: KDH | I25: GMD | J25: SBT | K25: DCM | L25: MSN | M25: MWG | N25: FPT | O25: VNM | P25: PNJ | Q25: REE | R25: VCB | S25: BID | T25: CTG | U25: PVD | V25: Tổng | W25: Phương sai danh mục
A26: Tỷ trọng đầu tư vào mỗi chứng khoán | B26: 0 | C26: 0 | D26: 0 | E26: 0.0012048355 | F26: 0 | G26: 0 | H26: 0.35492506 | I26: 0 | J26: 0 | K26: 0.13629786 | L26: 0.046889666 | M26: 0 | N26: 0 | O26: 0 | P26: 0 | Q26: 0.27823935 | R26: 0.18244323 | S26: 0 | T26: 0 | U26: 0 | V26: =SUM(B26:U26) -> 1 | W26: {=MMULT(MMULT(B26:U26,B5:U24),TRANSPOSE(B26:U26))} -> 0.0038145669
A27: Điều kiện ràng buộc | B27: <=40% | C27: <=40% | D27: <=40% | E27: <=40% | F27: <=40% | G27: <=40% | H27: <=40% | I27: <=40% | J27: <=40% | K27: <=40% | L27: <=40% | M27: <=40% | N27: <=40% | O27: <=40% | P27: <=40% | Q27: <=40% | R27: <=40% | S27: <=40% | T27: <=40% | U27: <=40% | V27: 1
A28: Tỷ suất sinh lợi kỳ vọng | B28: ? | C28: ? | D28: ? | E28: ? | F28: ? | G28: ? | H28: ? | I28: ? | J28: ? | K28: ? | L28: ? | M28: ? | N28: ? | O28: ? | P28: ? | Q28: ? | R28: ? | S28: ? | T28: ? | U28: ? | V28: =SUMPRODUCT(B2:U2,B26:U26) -> 0.02 | W28: >=2%
A30: Các điều kiện ràng buộc như sau: | G30: DANH MỤC TỐI ƯU HÓA
A31: (1) Danh mục đầu tư hết | G31: MSN | I31: =L26 -> 0.046889666
A32: (2) TSSL của danh mục tối thiểu là 2% | G32: DCM | I32: =K26 -> 0.13629786
A33: (3) Thị trường không cho bán khống chứng khoán | G33: VCB | I33: =R26 -> 0.18244323
A34: (4) % Vốn đầu tư vào mỗi chứng khoán không được vượt quá 40% | G34: REE | I34: =Q26 -> 0.27823935
G35: KDH | I35: =H26 -> 0.35492506
G36: Tổng | I36: =SUM(I31:I35) -> 0.99879516

Sheet DMĐT hiệu quả có bán khống
A1: MA TRẬN PHƯƠNG SAI - HIỆP PHƯƠNG SAI
B2: HPG | C2: HSG | D2: NKG | E2: KBC | F2: NLG | G2: DXG | H2: KDH | I2: GMD | J2: SBT | K2: DCM | L2: MSN | M2: MWG | N2: FPT | O2: VNM | P2: PNJ | Q2: REE | R2: VCB | S2: BID | T2: CTG | U2: PVD
A3: HPG | B3: 0.01733143 | C3: 0.011356876 | D3: 0.011913333 | E3: 0.0044035668 | F3: 0.0029420677 | G3: 0.0077061855 | H3: 0.004460181 | I3: 0.0051961432 | J3: 0.0035981619 | K3: 0.003908859 | L3: 0.0048341776 | M3: 0.0055966939 | N3: 0.0039041846 | O3: 0.0016974418 | P3: 0.013145934 | Q3: 0.0032729224 | R3: 0.0053817854 | S3: 0.0062980454 | T3: 0.0075520291 | U3: 0.0096242282
A4: HSG | B4: 0.011356876 | C4: 0.033767415 | D4: 0.023193916 | E4: 0.0067899037 | F4: 0.0061758944 | G4: 0.011397768 | H4: 0.0064809191 | I4: 0.0069565122 | J4: 0.0078550063 | K4: 0.0097546717 | L4: 0.0054934183 | M4: 0.0154218 | N4: 0.0082513387 | O4: 0.0040849158 | P4: 0.0089863936 | Q4: 0.0059823037 | R4: 0.0077341288 | S4: 0.0087949218 | T4: 0.010323383 | U4: 0.017531088
A5: NKG | B5: 0.011913333 | C5: 0.023193916 | D5: 0.031051664 | E5: 0.0081754764 | F5: 0.0067264828 | G5: 0.01147288 | H5: 0.0085735107 | I5: 0.0093486331 | J5: 0.0096084982 | K5: 0.010541537 | L5: 0.0047368086 | M5: 0.010711933 | N5: 0.0074717441 | O5: 0.0040777817 | P5: 0.010971918 | Q5: 0.0071538232 | R5: 0.0074776589 | S5: 0.01068389 | T5: 0.011404422 | U5: 0.016633384
A6: KBC | B6: 0.0044035668 | C6: 0.0067899037 | D6: 0.0081754764 | E6: 0.011751647 | F6: 0.0029503709 | G6: 0.0061017827 | H6: 0.0033222056 | I6: 0.0043842493 | J6: 0.0051603559 | K6: 0.004859424 | L6: 0.00083908638 | M6: 0.0025692646 | N6: 0.0027564962 | O6: 0.0020689986 | P6: 0.0048691799 | Q6: 0.003574817 | R6: 0.0030209386 | S6: 0.0028373545 | T6: 0.0024729024 | U6: 0.0087930709
A7: NLG | B7: 0.0029420677 | C7: 0.0061758944 | D7: 0.0067264828 | E7: 0.0029503709 | F7: 0.0069549443 | G7: 0.0059432781 | H7: 0.0043594371 | I7: 0.0022731255 | J7: 0.00383007 | K7: 0.0030769096 | L7: 0.0033652547 | M7: 0.0034664135 | N7: 0.0043335352 | O7: 0.0024836272 | P7: 0.0054289508 | Q7: 0.0037598161 | R7: 0.0024020786 | S7: 0.004392292 | T7: 0.0036049792 | U7: 0.006435244
A8: DXG | B8: 0.0077061855 | C8: 0.011397768 | D8: 0.01147288 | E8: 0.0061017827 | F8: 0.0059432781 | G8: 0.019682558 | H8: 0.0065577936 | I8: 0.0054706059 | J8: 0.0063981151 | K8: 0.0058545612 | L8: 0.0052916712 | M8: 0.0089388644 | N8: 0.0072378042 | O8: 0.0035126051 | P8: 0.010050506 | Q8: 0.0047861857 | R8: 0.0045487678 | S8: 0.0082170211 | T8: 0.0087897854 | U8: 0.012429732
A9: KDH | B9: 0.004460181 | C9: 0.0064809191 | D9: 0.0085735107 | E9: 0.0033222056 | F9: 0.0043594371 | G9: 0.0065577936 | H9: 0.0069581829 | I9: 0.0034383944 | J9: 0.0026433416 | K9: 0.0020862577 | L9: 0.0032173792 | M9: 0.0043644499 | N9: 0.0042115839 | O9: 0.0014470541 | P9: 0.0058999224 | Q9: 0.0028651755 | R9: 0.0024380403 | S9: 0.0052556481 | T9: 0.0035857459 | U9: 0.0067601069
A10: GMD | B10: 0.0051961432 | C10: 0.0069565122 | D10: 0.0093486331 | E10: 0.0043842493 | F10: 0.0022731255 | G10: 0.0054706059 | H10: 0.0034383944 | I10: 0.0094280971 | J10: 0.0051220155 | K10: 0.0057401311 | L10: 0.0015276943 | M10: 0.0042058695 | N10: 0.0038690453 | O10: 0.0022153384 | P10: 0.0043614748 | Q10: 0.0040961581 | R10: 0.0035431911 | S10: 0.0035795968 | T10: 0.0041659119 | U10: 0.008201027
A11: SBT | B11: 0.0035981619 | C11: 0.0078550063 | D11: 0.0096084982 | E11: 0.0051603559 | F11: 0.00383007 | G11: 0.0063981151 | H11: 0.0026433416 | I11: 0.0051220155 | J11: 0.014616828 | K11: 0.0060839061 | L11: 0.00020824084 | M11: 0.0028339775 | N11: 0.0045420264 | O11: 0.0024566841 | P11: 0.0055079124 | Q11: 0.0056495974 | R11: 0.0041047545 | S11: 0.0064591782 | T11: 0.0070249882 | U11: 0.0088712215
A12: DCM | B12: 0.003908859 | C12: 0.0097546717 | D12: 0.010541537 | E12: 0.004859424 | F12: 0.0030769096 | G12: 0.0058545612 | H12: 0.0020862577 | I12: 0.0057401311 | J12: 0.0060839061 | K12: 0.01297718 | L12: 0.0030263042 | M12: 0.0041848135 | N12: 0.0033046791 | O12: 0.0020421376 | P12: 0.0038390925 | Q12: 0.0030246963 | R12: 0.0019773379 | S12: 0.0029777594 | T12: 0.0034600574 | U12: 0.0080651735
A13: MSN | B13: 0.0048341776 | C13: 0.0054934183 | D13: 0.0047368086 | E13: 0.00083908638 | F13: 0.0033652547 | G13: 0.0052916712 | H13: 0.0032173792 | I13: 0.0015276943 | J13: 0.00020824084 | K13: 0.0030263042 | L13: 0.014799499 | M13: 0.0025298652 | N13: 0.0034038056 | O13: 0.0025061751 | P13: 0.0047433146 | Q13: 0.0014452854 | R13: 0.0013937671 | S13: 0.001840803 | T13: 0.0008749074 | U13: 0.0043553896
A14: MWG | B14: 0.0055966939 | C14: 0.0154218 | D14: 0.010711933 | E14: 0.0025692646 | F14: 0.0034664135 | G14: 0.0089388644 | H14: 0.0043644499 | I14: 0.0042058695 | J14: 0.0028339775 | K14: 0.0041848135 | L14: 0.0025298652 | M14: 0.022180465 | N14: 0.0062497671 | O14: 0.0020711003 | P14: 0.0075658576 | Q14: 0.0017789286 | R14: 0.0049048584 | S14: 0.0048914276 | T14: 0.0055534539 | U14: 0.010698643
... A22: PVD | B22: 0.0096242282 | C22: 0.017531088 | D22: 0.016633384 | E22: 0.0087930709 | F22: 0.006435244 | G22: 0.012429732 | H22: 0.0067601069 | I22: 0.008201027 | J22: 0.0088712215 | K22: 0.0080651735 | L22: 0.0043553896 | M22: 0.010698643 | N22: 0.0083191221 | O22: 0.004846898 | P22: 0.0084733862 | Q22: 0.0068173047 | R22: 0.0079876935 | S22: 0.0096178234 | T22: 0.010273468 | U22: 0.023088805
A24: Hằng số c1 = | B24: =6.253%/12 -> 0.0052108333 | E24: Hằng số c2 = | F24: =4.048%/12 -> 0.0033733333
A25: DANH MỤC X | E25: DANH MỤC Y
A26: Mã chứng khoán | B26: TSSL trung bình | C26: Tỷ trọng đầu tư | E26: Mã chứng khoán | F26: TSSL trung bình | G26: Tỷ trọng đầu tư
A27: HPG | B27: ='Các chỉ tiêu cơ bản'!B2 -> 0.0030056316 | C27: {=MMULT(MINVERSE(B3:U22),B27:B46-B24)/SUM(MMULT(MINVERSE(B3:U22),B27:B46-B24))} -> -0.45948176 | E27: HPG | F27: ='Các chỉ tiêu cơ bản'!B2 -> 0.0030056316 | G27: {=MMULT(MINVERSE(B3:U22),F27:F46-F24)/SUM(MMULT(MINVERSE(B3:U22),F27:F46-F24))} -> -0.32377364
A28: HSG | B28: ='Các chỉ tiêu cơ bản'!C2 -> -0.00020595048 | C28: -0.25936727 | E28: HSG | F28: ='Các chỉ tiêu cơ bản'!C2 -> -0.00020595048 | G28: -0.21732591
A29: NKG | B29: ='Các chỉ tiêu cơ bản'!D2 -> 0.016297054 | C29: -0.041277774 | E29: NKG | F29: ='Các chỉ tiêu cơ bản'!D2 -> 0.016297054 | G29: -0.060898963
A30: KBC | B30: ='Các chỉ tiêu cơ bản'!E2 -> 0.017304144 | C30: 0.17032402 | E30: KBC | F30: ='Các chỉ tiêu cơ bản'!E2 -> 0.017304144 | G30: 0.16414607
A31: NLG | B31: ='Các chỉ tiêu cơ bản'!F2 -> 0.015445248 | C31: -0.2245257 | E31: NLG | F31: ='Các chỉ tiêu cơ bản'!F2 -> 0.015445248 | G31: -0.17074808
A32: DXG | B32: ='Các chỉ tiêu cơ bản'!G2 -> 0.028375651 | C32: 0.4272645 | E32: DXG | F32: ='Các chỉ tiêu cơ bản'!G2 -> 0.028375651 | G32: 0.31926631
A33: KDH | B33: ='Các chỉ tiêu cơ bản'!H2 -> 0.022425396 | C33: 0.75622483 | E33: KDH | F33: ='Các chỉ tiêu cơ bản'!H2 -> 0.022425396 | G33: 0.66391581
A34: GMD | B34: ='Các chỉ tiêu cơ bản'!I2 -> 0.0099147215 | C34: -0.54565792 | E34: GMD | F34: ='Các chỉ tiêu cơ bản'!I2 -> 0.0099147215 | G34: -0.43729348
A35: SBT | B35: ='Các chỉ tiêu cơ bản'!J2 -> 0.0010267414 | C35: -0.70749232 | E35: SBT | F35: ='Các chỉ tiêu cơ bản'!J2 -> 0.0010267414 | G35: -0.554848
A36: DCM | B36: ='Các chỉ tiêu cơ bản'!K2 -> 0.020322801 | C36: 0.90105447 | E36: DCM | F36: ='Các chỉ tiêu cơ bản'!K2 -> 0.020322801 | G36: 0.74653023
A37: MSN | B37: ='Các chỉ tiêu cơ bản'!L2 -> 0.013445717 | C37: 0.1691543 | E37: MSN | F37: ='Các chỉ tiêu cơ bản'!L2 -> 0.013445717 | G37: 0.14252312
A38: MWG | B38: ='Các chỉ tiêu cơ bản'!M2 -> -0.00070458185 | C38: -0.1753775 | E38: MWG | F38: ='Các chỉ tiêu cơ bản'!M2 -> -0.00070458185 | G38: -0.11409237
A39: FPT | B39: ='Các chỉ tiêu cơ bản'!N2 -> 0.013163614 | C39: 0.42446826 | E39: FPT | F39: ='Các chỉ tiêu cơ bản'!N2 -> 0.013163614 | G39: 0.36314833
A40: VNM | B40: ='Các chỉ tiêu cơ bản'!O2 -> -0.0079187879 | C40: -2.2186807 | E40: VNM | F40: ='Các chỉ tiêu cơ bản'!O2 -> -0.0079187879 | G40: -1.7059681
A41: PNJ | B41: ='Các chỉ tiêu cơ bản'!P2 -> 0.0059744073 | C41: -0.032489386 | E41: PNJ | F41: ='Các chỉ tiêu cơ bản'!P2 -> 0.0059744073 | G41: -0.068572414
A42: REE | B42: ='Các chỉ tiêu cơ bản'!Q2 -> 0.019659931 | C42: 1.6196283 | E42: REE | F42: ='Các chỉ tiêu cơ bản'!Q2 -> 0.019659931 | G42: 1.3217474
A43: VCB | B43: ='Các chỉ tiêu cơ bản'!R2 -> 0.017261427 | C43: 2.1737287 | E43: VCB | F43: ='Các chỉ tiêu cơ bản'!R2 -> 0.017261427 | G43: 1.7374125
A44: BID | B44: ='Các chỉ tiêu cơ bản'!S2 -> 0.018218042 | C44: -0.31513686 | E44: BID | F44: ='Các chỉ tiêu cơ bản'!S2 -> 0.018218042 | G44: -0.24918983
A45: CTG | B45: ='Các chỉ tiêu cơ bản'!T2 -> 0.012801305 | C45: -0.038060675 | E45: CTG | F45: ='Các chỉ tiêu cơ bản'!T2 -> 0.012801305 | G45: -0.010765609
A46: PVD | B46: ='Các chỉ tiêu cơ bản'!U2 -> 0.001881973 | C46: -0.62429952 | E46: PVD | F46: ='Các chỉ tiêu cơ bản'!U2 -> 0.001881973 | G46: -0.54521336
A47: Tổng | C47: =SUM(C27:C46) -> 1 | E47: Tổng | G47: =SUM(G27:G46) -> 1
A48: E(x) | C48: =SUMPRODUCT(B27:B46,C27:C46) -> 0.12605796 | E48: E(y) | G48: =SUMPRODUCT(F27:F46,G27:G46) -> 0.10264514
...

Sheet DMĐT hiệu quả ko bán khống
A1: MA TRẬN PHƯƠNG SAI - HIỆP PHƯƠNG SAI
B2: HPG | C2: HSG | D2: NKG | E2: KBC | F2: NLG | G2: DXG | H2: KDH | I2: GMD | J2: SBT | K2: DCM | L2: MSN | M2: MWG | N2: FPT | O2: VNM | P2: PNJ | Q2: REE | R2: VCB | S2: BID | T2: CTG | U2: PVD
A3: HPG | B3: 0.01733143 | C3: 0.011356876 | D3: 0.011913333 | E3: 0.0044035668 | F3: 0.0029420677 | G3: 0.0077061855 | H3: 0.004460181 | I3: 0.0051961432 | J3: 0.0035981619 | K3: 0.003908859 | L3: 0.0048341776 | M3: 0.0055966939 | N3: 0.0039041846 | O3: 0.0016974418 | P3: 0.013145934 | Q3: 0.0032729224 | R3: 0.0053817854 | S3: 0.0062980454 | T3: 0.0075520291 | U3: 0.0096242282
A4: HSG | B4: 0.011356876 | C4: 0.033767415 | D4: 0.023193916 | E4: 0.0067899037 | F4: 0.0061758944 | G4: 0.011397768 | H4: 0.0064809191 | I4: 0.0069565122 | J4: 0.0078550063 | K4: 0.0097546717 | L4: 0.0054934183 | M4: 0.0154218 | N4: 0.0082513387 | O4: 0.0040849158 | P4: 0.0089863936 | Q4: 0.0059823037 | R4: 0.0077341288 | S4: 0.0087949218 | T4: 0.010323383 | U4: 0.017531088
A5: NKG | B5: 0.011913333 | C5: 0.023193916 | D5: 0.031051664 | E5: 0.0081754764 | F5: 0.0067264828 | G5: 0.01147288 | H5: 0.0085735107 | I5: 0.0093486331 | J5: 0.0096084982 | K5: 0.010541537 | L5: 0.0047368086 | M5: 0.010711933 | N5: 0.0074717441 | O5: 0.0040777817 | P5: 0.010971918 | Q5: 0.0071538232 | R5: 0.0074776589 | S5: 0.01068389 | T5: 0.011404422 | U5: 0.016633384
A6: KBC | B6: 0.0044035668 | C6: 0.0067899037 | D6: 0.0081754764 | E6: 0.011751647 | F6: 0.0029503709 | G6: 0.0061017827 | H6: 0.0033222056 | I6: 0.0043842493 | J6: 0.0051603559 | K6: 0.004859424 | L6: 0.00083908638 | M6: 0.0025692646 | N6: 0.0027564962 | O6: 0.0020689986 | P6: 0.0048691799 | Q6: 0.003574817 | R6: 0.0030209386 | S6: 0.0028373545 | T6: 0.0024729024 | U6: 0.0087930709
A7: NLG | B7: 0.0029420677 | C7: 0.0061758944 | D7: 0.0067264828 | E7: 0.0029503709 | F7: 0.0069549443 | G7: 0.0059432781 | H7: 0.0043594371 | I7: 0.0022731255 | J7: 0.00383007 | K7: 0.0030769096 | L7: 0.0033652547 | M7: 0.0034664135 | N7: 0.0043335352 | O7: 0.0024836272 | P7: 0.0054289508 | Q7: 0.0037598161 | R7: 0.0024020786 | S7: 0.004392292 | T7: 0.0036049792 | U7: 0.006435244
A8: DXG | B8: 0.0077061855 | C8: 0.011397768 | D8: 0.01147288 | E8: 0.0061017827 | F8: 0.0059432781 | G8: 0.019682558 | H8: 0.0065577936 | I8: 0.0054706059 | J8: 0.0063981151 | K8: 0.0058545612 | L8: 0.0052916712 | M8: 0.0089388644 | N8: 0.0072378042 | O8: 0.0035126051 | P8: 0.010050506 | Q8: 0.0047861857 | R8: 0.0045487678 | S8: 0.0082170211 | T8: 0.0087897854 | U8: 0.012429732
A9: KDH | B9: 0.004460181 | C9: 0.0064809191 | D9: 0.0085735107 | E9: 0.0033222056 | F9: 0.0043594371 | G9: 0.0065577936 | H9: 0.0069581829 | I9: 0.0034383944 | J9: 0.0026433416 | K9: 0.0020862577 | L9: 0.0032173792 | M9: 0.0043644499 | N9: 0.0042115839 | O9: 0.0014470541 | P9: 0.0058999224 | Q9: 0.0028651755 | R9: 0.0024380403 | S9: 0.0052556481 | T9: 0.0035857459 | U9: 0.0067601069
A10: GMD | B10: 0.0051961432 | C10: 0.0069565122 | D10: 0.0093486331 | E10: 0.0043842493 | F10: 0.0022731255 | G10: 0.0054706059 | H10: 0.0034383944 | I10: 0.0094280971 | J10: 0.0051220155 | K10: 0.0057401311 | L10: 0.0015276943 | M10: 0.0042058695 | N10: 0.0038690453 | O10: 0.0022153384 | P10: 0.0043614748 | Q10: 0.0040961581 | R10: 0.0035431911 | S10: 0.0035795968 | T10: 0.0041659119 | U10: 0.008201027
A11: SBT | B11: 0.0035981619 | C11: 0.0078550063 | D11: 0.0096084982 | E11: 0.0051603559 | F11: 0.00383007 | G11: 0.0063981151 | H11: 0.0026433416 | I11: 0.0051220155 | J11: 0.014616828 | K11: 0.0060839061 | L11: 0.00020824084 | M11: 0.0028339775 | N11: 0.0045420264 | O11: 0.0024566841 | P11: 0.0055079124 | Q11: 0.0056495974 | R11: 0.0041047545 | S11: 0.0064591782 | T11: 0.0070249882 | U11: 0.0088712215
A12: DCM | B12: 0.003908859 | C12: 0.0097546717 | D12: 0.010541537 | E12: 0.004859424 | F12: 0.0030769096 | G12: 0.0058545612 | H12: 0.0020862577 | I12: 0.0057401311 | J12: 0.0060839061 | K12: 0.01297718 | L12: 0.0030263042 | M12: 0.0041848135 | N12: 0.0033046791 | O12: 0.0020421376 | P12: 0.0038390925 | Q12: 0.0030246963 | R12: 0.0019773379 | S12: 0.0029777594 | T12: 0.0034600574 | U12: 0.0080651735
A13: MSN | B13: 0.0048341776 | C13: 0.0054934183 | D13: 0.0047368086 | E13: 0.00083908638 | F13: 0.0033652547 | G13: 0.0052916712 | H13: 0.0032173792 | I13: 0.0015276943 | J13: 0.00020824084 | K13: 0.0030263042 | L13: 0.014799499 | M13: 0.0025298652 | N13: 0.0034038056 | O13: 0.0025061751 | P13: 0.0047433146 | Q13: 0.0014452854 | R13: 0.0013937671 | S13: 0.001840803 | T13: 0.0008749074 | U13: 0.0043553896
A14: MWG | B14: 0.0055966939 | C14: 0.0154218 | D14: 0.010711933 | E14: 0.0025692646 | F14: 0.0034664135 | G14: 0.0089388644 | H14: 0.0043644499 | I14: 0.0042058695 | J14: 0.0028339775 | K14: 0.0041848135 | L14: 0.0025298652 | M14: 0.022180465 | N14: 0.0062497671 | O14: 0.0020711003 | P14: 0.0075658576 | Q14: 0.0017789286 | R14: 0.0049048584 | S14: 0.0048914276 | T14: 0.0055534539 | U14: 0.010698643
... A22: PVD | B22: 0.0096242282 | C22: 0.017531088 | D22: 0.016633384 | E22: 0.0087930709 | F22: 0.006435244 | G22: 0.012429732 | H22: 0.0067601069 | I22: 0.008201027 | J22: 0.0088712215 | K22: 0.0080651735 | L22: 0.0043553896 | M22: 0.010698643 | N22: 0.0083191221 | O22: 0.004846898 | P22: 0.0084733862 | Q22: 0.0068173047 | R22: 0.0079876935 | S22: 0.0096178234 | T22: 0.010273468 | U22: 0.023088805
A24: DANH MỤC X | E24: DANH MỤC ĐẦU TƯ HIỆU QUẢ KHÔNG BÁN KHỐNG
A25: Mã chứng khoán | B25: TSSL trung bình | C25: Tỷ trọng đầu tư | F25: DXG | G25: =C31 -> 0.024135658
A26: HPG | B26: ='Các chỉ tiêu cơ bản'!B2 -> 0.0030056316 | C26: 0 | F26: VCB | G26: =C42 -> 0.12818095
A27: HSG | B27: ='Các chỉ tiêu cơ bản'!C2 -> -0.00020595048 | C27: 0 | F27: DCM | G27: =C35 -> 0.14661615
A28: NKG | B28: ='Các chỉ tiêu cơ bản'!D2 -> 0.016297054 | C28: 0 | F28: REE | G28: =C41 -> 0.27192038
A29: KBC | B29: ='Các chỉ tiêu cơ bản'!E2 -> 0.017304144 | C29: 0 | F29: KDH | G29: =C32 -> 0.42914687
A30: NLG | B30: ='Các chỉ tiêu cơ bản'!F2 -> 0.015445248 | C30: 0 | E30: Tổng | G30: =SUM(G25:G29) -> 1
A31: DXG | B31: ='Các chỉ tiêu cơ bản'!G2 -> 0.028375651 | C31: 0.024135658
A32: KDH | B32: ='Các chỉ tiêu cơ bản'!H2 -> 0.022425396 | C32: 0.42914687
A33: GMD | B33: ='Các chỉ tiêu cơ bản'!I2 -> 0.0099147215 | C33: 0
A34: SBT | B34: ='Các chỉ tiêu cơ bản'!J2 -> 0.0010267414 | C34: 0
A35: DCM | B35: ='Các chỉ tiêu cơ bản'!K2 -> 0.020322801 | C35: 0.14661615
A36: MSN | B36: ='Các chỉ tiêu cơ bản'!L2 -> 0.013445717 | C36: 0
A37: MWG | B37: ='Các chỉ tiêu cơ bản'!M2 -> -0.00070458185 | C37: 0
A38: FPT | B38: ='Các chỉ tiêu cơ bản'!N2 -> 0.013163614 | C38: 0
A39: VNM | B39: ='Các chỉ tiêu cơ bản'!O2 -> -0.0079187879 | C39: 0
A40: PNJ | B40: ='Các chỉ tiêu cơ bản'!P2 -> 0.0059744073 | C40: 0
A41: REE | B41: ='Các chỉ tiêu cơ bản'!Q2 -> 0.019659931 | C41: 0.27192038
A42: VCB | B42: ='Các chỉ tiêu cơ bản'!R2 -> 0.017261427 | C42: 0.12818095
A43: BID | B43: ='Các chỉ tiêu cơ bản'!S2 -> 0.018218042 | C43: 0
A44: CTG | B44: ='Các chỉ tiêu cơ bản'!T2 -> 0.012801305 | C44: 0
A45: PVD | B45: ='Các chỉ tiêu cơ bản'!U2 -> 0.001881973 | C45: 0
A46: Tổng | C46: =SUM(C26:C45) -> 1
A47: Hằng số c | C47: =AVERAGE('DMĐT hiệu quả có bán khống'!B24:C24,'DMĐT hiệu quả có bán khống'!F24:G24) -> 0.0042920833
A48: TSSL của danh mục | C48: =SUMPRODUCT(B26:B45,C26:C45) -> 0.020846826
...
